<?xml version="1.0" ?>
<sdf version='1.6'>
  <world name='default'>
    <light name='sun' type='directional'>
      <cast_shadows>1</cast_shadows>
      <pose frame=''>0 0 10 0 -0 0</pose>
      <diffuse>0.8 0.8 0.8 1</diffuse>
      <specular>0.2 0.2 0.2 1</specular>
      <attenuation>
        <range>1000</range>
        <constant>0.9</constant>
        <linear>0.01</linear>
        <quadratic>0.001</quadratic>
      </attenuation>
      <direction>-0.5 0.1 -0.9</direction>
    </light>
    <model name='ground_plane'>
      <static>1</static>
      <link name='link'>
        <collision name='collision'>
          <geometry>
            <plane>
              <normal>0 0 1</normal>
              <size>100 100</size>
            </plane>
          </geometry>
          <surface>
            <friction>
              <ode>
                <mu>100</mu>
                <mu2>50</mu2>
              </ode>
              <torsional>
                <ode/>
              </torsional>
            </friction>
            <contact>
              <ode/>
            </contact>
            <bounce/>
          </surface>
          <max_contacts>10</max_contacts>
        </collision>
        <visual name='visual'>
          <cast_shadows>0</cast_shadows>
          <geometry>
            <plane>
              <normal>0 0 1</normal>
              <size>100 100</size>
            </plane>
          </geometry>
          <material>
            <script>
              <uri>file://media/materials/scripts/gazebo.material</uri>
              <name>Gazebo/Grey</name>
            </script>
          </material>
        </visual>
        <self_collide>0</self_collide>
        <enable_wind>0</enable_wind>
        <kinematic>0</kinematic>
      </link>
    </model>
    <gravity>0 0 -9.8</gravity>
    <magnetic_field>6e-06 2.3e-05 -4.2e-05</magnetic_field>
    <atmosphere type='adiabatic'/>
    <physics name='default_physics' default='0' type='ode'>
      <max_step_size>0.001</max_step_size>
      <real_time_factor>1</real_time_factor>
      <real_time_update_rate>1000</real_time_update_rate>
    </physics>
    <scene>
      <ambient>0.4 0.4 0.4 1</ambient>
      <background>0.7 0.7 0.7 1</background>
      <shadows>1</shadows>
    </scene>
    <audio>
      <device>default</device>
    </audio>
    <wind/>
    <spherical_coordinates>
      <surface_model>EARTH_WGS84</surface_model>
      <latitude_deg>0</latitude_deg>
      <longitude_deg>0</longitude_deg>
      <elevation>0</elevation>
      <heading_deg>0</heading_deg>
    </spherical_coordinates>
    <model name='SIM_CER_ROBOT'>
      <link name='mobile_base_body_link'>
        <pose frame=''>0 0 0 0 -0 0</pose>
        <inertial>
          <pose frame=''>0.003532 0 0.062803 0 -0 0</pose>
          <mass>14</mass>
          <inertia>
            <ixx>0.342401</ixx>
            <ixy>0</ixy>
            <ixz>-0.0396992</ixz>
            <iyy>0.362542</iyy>
            <iyz>0</iyz>
            <izz>0.168981</izz>
          </inertia>
        </inertial>
        <collision name='mobile_base_body_link_collision'>
          <pose frame=''>0 0 -0.16 0 -0 0</pose>
          <geometry>
            <mesh>
              <scale>0.001 0.001 0.001</scale>
              <uri>model://cer/meshes/dae/sim_cer_mobilebase_body.dae</uri>
            </mesh>
          </geometry>
          <surface>
            <contact>
              <ode/>
            </contact>
            <friction>
              <ode>
                <mu>0.1</mu>
                <mu2>0.1</mu2>
              </ode>
              <torsional>
                <ode/>
              </torsional>
            </friction>
            <bounce/>
          </surface>
          <max_contacts>10</max_contacts>
        </collision>
        <visual name='mobile_base_body_link_visual'>
          <pose frame=''>0 0 -0.16 0 -0 0</pose>
          <geometry>
            <mesh>
              <scale>0.001 0.001 0.001</scale>
              <uri>model://cer/meshes/dae/sim_cer_mobilebase_body.dae</uri>
            </mesh>
          </geometry>
          <material>
            <script>
              <uri>__default__</uri>
              <name>__default__</name>
            </script>
          </material>
        </visual>
        <velocity_decay/>
        <sensor name='base_laser' type='ray'>
          <always_on>1</always_on>
          <update_rate>40</update_rate>
          <pose frame=''>0.07 0 0.031 0 -0 0</pose>
          <ray>
            <scan>
              <horizontal>
                <samples>360</samples>
                <resolution>1</resolution>
                <min_angle>-3.14</min_angle>
                <max_angle>3.14</max_angle>
              </horizontal>
              <vertical>
                <samples>1</samples>
                <min_angle>0</min_angle>
                <max_angle>0</max_angle>
              </vertical>
            </scan>
            <range>
              <min>0.1</min>
              <max>5</max>
              <resolution>0.01</resolution>
            </range>
            <noise>
              <type>gaussian</type>
              <mean>0</mean>
              <stddev>0.005</stddev>
            </noise>
          </ray>
          <plugin name='laser_sensor' filename='libgazebo_yarp_lasersensor.so'>
            <yarpConfigurationFile>model://cer/conf/gazebo_cer_laser_sensor.ini</yarpConfigurationFile>
          </plugin>
        </sensor>
        <gravity>1</gravity>
        <velocity_decay/>
        <self_collide>0</self_collide>
        <enable_wind>0</enable_wind>
        <kinematic>0</kinematic>
      </link>
      <link name='mobile_base_l_tyre_link'>
        <pose frame=''>0 0.139 0 0 -0 0</pose>
        <inertial>
          <pose frame=''>0 0.034425 9e-06 0 -0 0</pose>
          <mass>3</mass>
          <inertia>
            <ixx>0.0200196</ixx>
            <ixy>0</ixy>
            <ixz>0</ixz>
            <iyy>0.0376169</iyy>
            <iyz>-8.28446e-07</iyz>
            <izz>0.0200156</izz>
          </inertia>
        </inertial>
        <collision name='mobile_base_l_tyre_link_collision'>
          <pose frame=''>0 0.03 0 1.5708 -0 0</pose>
          <geometry>
            <cylinder>
              <length>0.005</length>
              <radius>0.16</radius>
            </cylinder>
          </geometry>
          <max_contacts>10</max_contacts>
          <surface>
            <contact>
              <ode/>
            </contact>
            <bounce/>
            <friction>
              <ode>
                <mu>0.1</mu>
                <mu2>0.1</mu2>
              </ode>
              <torsional>
                <ode/>
              </torsional>
              <ode/>
            </friction>
          </surface>
        </collision>
        <visual name='mobile_base_l_tyre_link_visual'>
          <pose frame=''>0 -0.139 -0.16 0 -0 0</pose>
          <geometry>
            <mesh>
              <scale>0.001 0.001 0.001</scale>
              <uri>model://cer/meshes/dae/sim_cer_mobilebase_l_tyre.dae</uri>
            </mesh>
          </geometry>
        </visual>
        <self_collide>0</self_collide>
        <enable_wind>0</enable_wind>
        <kinematic>0</kinematic>
      </link>
      <joint name='mobile_base_l_wheel_joint' type='revolute'>
        <child>mobile_base_l_tyre_link</child>
        <parent>mobile_base_body_link</parent>
        <axis>
          <xyz>0 1 0</xyz>
          <limit>
            <lower>-1e+16</lower>
            <upper>1e+16</upper>
          </limit>
          <dynamics>
            <damping>0.5</damping>
            <friction>0</friction>
            <spring_reference>0</spring_reference>
            <spring_stiffness>0</spring_stiffness>
          </dynamics>
          <use_parent_model_frame>1</use_parent_model_frame>
        </axis>
        <physics>
          <ode>
            <implicit_spring_damper>1</implicit_spring_damper>
            <cfm_damping>1</cfm_damping>
            <limit>
              <cfm>0</cfm>
              <erp>0.2</erp>
            </limit>
          </ode>
        </physics>
      </joint>
      <link name='mobile_base_r_tyre_link'>
        <pose frame=''>0 -0.139 0 0 -0 0</pose>
        <inertial>
          <pose frame=''>0 -0.034425 9e-06 0 -0 0</pose>
          <mass>3</mass>
          <inertia>
            <ixx>0.0200196</ixx>
            <ixy>0</ixy>
            <ixz>0</ixz>
            <iyy>0.0376169</iyy>
            <iyz>8.28101e-07</iyz>
            <izz>0.0200156</izz>
          </inertia>
        </inertial>
        <collision name='mobile_base_r_tyre_link_collision'>
          <pose frame=''>0 -0.03 0 1.5708 -0 0</pose>
          <geometry>
            <cylinder>
              <length>0.005</length>
              <radius>0.16</radius>
            </cylinder>
          </geometry>
          <max_contacts>10</max_contacts>
          <surface>
            <contact>
              <ode/>
            </contact>
            <bounce/>
            <friction>
              <ode>
                <mu>0.1</mu>
                <mu2>0.1</mu2>
              </ode>
              <torsional>
                <ode/>
              </torsional>
              <ode/>
            </friction>
          </surface>
        </collision>
        <visual name='mobile_base_r_tyre_link_visual'>
          <pose frame=''>0 0.139 -0.16 0 -0 0</pose>
          <geometry>
            <mesh>
              <scale>0.001 0.001 0.001</scale>
              <uri>model://cer/meshes/dae/sim_cer_mobilebase_r_tyre.dae</uri>
            </mesh>
          </geometry>
        </visual>
        <self_collide>0</self_collide>
        <enable_wind>0</enable_wind>
        <kinematic>0</kinematic>
      </link>
      <joint name='mobile_base_r_wheel_joint' type='revolute'>
        <child>mobile_base_r_tyre_link</child>
        <parent>mobile_base_body_link</parent>
        <axis>
          <xyz>0 1 0</xyz>
          <limit>
            <lower>-1e+16</lower>
            <upper>1e+16</upper>
          </limit>
          <dynamics>
            <damping>0.5</damping>
            <friction>0</friction>
            <spring_reference>0</spring_reference>
            <spring_stiffness>0</spring_stiffness>
          </dynamics>
          <use_parent_model_frame>1</use_parent_model_frame>
        </axis>
        <physics>
          <ode>
            <implicit_spring_damper>1</implicit_spring_damper>
            <cfm_damping>1</cfm_damping>
            <limit>
              <cfm>0</cfm>
              <erp>0.2</erp>
            </limit>
          </ode>
        </physics>
      </joint>
      <link name='torso_slider_eq_link'>
        <pose frame=''>0.044 0 0.071 0 -0 0</pose>
        <inertial>
          <pose frame=''>0.015175 3e-06 0.244533 0 -0 0</pose>
          <mass>7.5</mass>
          <inertia>
            <ixx>0.0978792</ixx>
            <ixy>-1.83466e-06</ixy>
            <ixz>0.00625726</ixz>
            <iyy>0.0969511</iyy>
            <iyz>0</iyz>
            <izz>0.0746114</izz>
          </inertia>
        </inertial>
        <collision name='torso_slider_eq_link_collision'>
          <pose frame=''>-0.044 0 -0.231 0 -0 0</pose>
          <geometry>
            <mesh>
              <scale>0.001 0.001 0.001</scale>
              <uri>model://cer/meshes/dae/sim_cer_torso_slider_eq.dae</uri>
            </mesh>
          </geometry>
          <max_contacts>10</max_contacts>
          <surface>
            <contact>
              <ode/>
            </contact>
            <bounce/>
            <friction>
              <torsional>
                <ode/>
              </torsional>
              <ode/>
            </friction>
          </surface>
        </collision>
        <visual name='torso_slider_eq_link_visual'>
          <pose frame=''>-0.044 0 -0.231 0 -0 0</pose>
          <geometry>
            <mesh>
              <scale>0.001 0.001 0.001</scale>
              <uri>model://cer/meshes/dae/sim_cer_torso_slider_eq.dae</uri>
            </mesh>
          </geometry>
        </visual>
        <self_collide>0</self_collide>
        <enable_wind>0</enable_wind>
        <kinematic>0</kinematic>
      </link>
      <joint name='torso_heave_eq_joint' type='prismatic'>
        <child>torso_slider_eq_link</child>
        <parent>mobile_base_body_link</parent>
        <axis>
          <xyz>0 0 1</xyz>
          <limit>
            <lower>0</lower>
            <upper>0.17</upper>
            <effort>1200</effort>
            <velocity>0.5</velocity>
          </limit>
          <dynamics>
            <damping>1000</damping>
            <friction>0</friction>
            <spring_reference>0</spring_reference>
            <spring_stiffness>0</spring_stiffness>
          </dynamics>
          <use_parent_model_frame>1</use_parent_model_frame>
        </axis>
        <physics>
          <ode>
            <implicit_spring_damper>1</implicit_spring_damper>
            <cfm_damping>1</cfm_damping>
            <limit>
              <cfm>0</cfm>
              <erp>0.2</erp>
            </limit>
          </ode>
        </physics>
      </joint>
      <link name='torso_pin_eq_link'>
        <pose frame=''>0.044 0 0.47 -3.14159 -0 0</pose>
        <inertial>
          <pose frame=''>0 0 0 0 -0 0</pose>
          <mass>1.5</mass>
          <inertia>
            <ixx>0.000379688</ixx>
            <ixy>0</ixy>
            <ixz>0</ixz>
            <iyy>0.00143984</iyy>
            <iyz>0</iyz>
            <izz>0.00143984</izz>
          </inertia>
        </inertial>
        <collision name='torso_pin_eq_link_collision'>
          <pose frame=''>0 0 0 0 -0 0</pose>
          <geometry>
            <mesh>
              <scale>0.001 0.001 0.001</scale>
              <uri>model://cer/meshes/dae/sim_cer_torso_pin_eq.dae</uri>
            </mesh>
          </geometry>
          <max_contacts>10</max_contacts>
          <surface>
            <contact>
              <ode/>
            </contact>
            <bounce/>
            <friction>
              <torsional>
                <ode/>
              </torsional>
              <ode/>
            </friction>
          </surface>
        </collision>
        <visual name='torso_pin_eq_link_visual'>
          <pose frame=''>0 0 0 0 -0 0</pose>
          <geometry>
            <mesh>
              <scale>0.001 0.001 0.001</scale>
              <uri>model://cer/meshes/dae/sim_cer_torso_pin_eq.dae</uri>
            </mesh>
          </geometry>
        </visual>
        <self_collide>0</self_collide>
        <enable_wind>0</enable_wind>
        <kinematic>0</kinematic>
      </link>
      <joint name='torso_roll_eq_joint' type='revolute'>
        <child>torso_pin_eq_link</child>
        <parent>torso_slider_eq_link</parent>
        <axis>
          <xyz>1 0 0</xyz>
          <limit>
            <lower>-0.523599</lower>
            <upper>0.523599</upper>
            <effort>50</effort>
            <velocity>3.14</velocity>
          </limit>
          <dynamics>
            <damping>100</damping>
            <friction>0</friction>
            <spring_reference>0</spring_reference>
            <spring_stiffness>0</spring_stiffness>
          </dynamics>
          <use_parent_model_frame>1</use_parent_model_frame>
        </axis>
        <physics>
          <ode>
            <implicit_spring_damper>1</implicit_spring_damper>
            <cfm_damping>1</cfm_damping>
            <limit>
              <cfm>0</cfm>
              <erp>0.2</erp>
            </limit>
          </ode>
        </physics>
      </joint>
      <link name='torso_platform_link'>
        <pose frame=''>0.044 0 0.47 0 -0 0</pose>
        <inertial>
          <pose frame=''>0 0 0 0 -0 0</pose>
          <mass>1.5</mass>
          <inertia>
            <ixx>0.00153125</ixx>
            <ixy>0</ixy>
            <ixz>0</ixz>
            <iyy>0.00153125</iyy>
            <iyz>0</iyz>
            <izz>0.0030375</izz>
          </inertia>
        </inertial>
        <collision name='torso_platform_link_collision'>
          <pose frame=''>-0.044 0 -0.63 0 -0 0</pose>
          <geometry>
            <mesh>
              <scale>0.001 0.001 0.001</scale>
              <uri>model://cer/meshes/dae/sim_cer_torso_platform.dae</uri>
            </mesh>
          </geometry>
          <max_contacts>10</max_contacts>
          <surface>
            <contact>
              <ode/>
            </contact>
            <bounce/>
            <friction>
              <torsional>
                <ode/>
              </torsional>
              <ode/>
            </friction>
          </surface>
        </collision>
        <visual name='torso_platform_link_visual'>
          <pose frame=''>-0.044 0 -0.63 0 -0 0</pose>
          <geometry>
            <mesh>
              <scale>0.001 0.001 0.001</scale>
              <uri>model://cer/meshes/dae/sim_cer_torso_platform.dae</uri>
            </mesh>
          </geometry>
        </visual>
        <self_collide>0</self_collide>
        <enable_wind>0</enable_wind>
        <kinematic>0</kinematic>
      </link>
      <joint name='torso_pitch_eq_joint' type='revolute'>
        <child>torso_platform_link</child>
        <parent>torso_pin_eq_link</parent>
        <axis>
          <xyz>0 1 0</xyz>
          <limit>
            <lower>-0.523599</lower>
            <upper>0.523599</upper>
            <effort>50</effort>
            <velocity>3.14</velocity>
          </limit>
          <dynamics>
            <damping>100</damping>
            <friction>0</friction>
            <spring_reference>0</spring_reference>
            <spring_stiffness>0</spring_stiffness>
          </dynamics>
          <use_parent_model_frame>1</use_parent_model_frame>
        </axis>
        <physics>
          <ode>
            <implicit_spring_damper>1</implicit_spring_damper>
            <cfm_damping>1</cfm_damping>
            <limit>
              <cfm>0</cfm>
              <erp>0.2</erp>
            </limit>
          </ode>
        </physics>
      </joint>
      <link name='chest_link'>
        <pose frame=''>0.044 0 0.47 0 -0 0</pose>
        <inertial>
          <pose frame=''>-0.033031 0 0.220198 0 -0 0</pose>
          <mass>13</mass>
          <inertia>
            <ixx>0.275816</ixx>
            <ixy>0</ixy>
            <ixz>0.0564476</ixz>
            <iyy>0.253579</iyy>
            <iyz>0</iyz>
            <izz>0.127156</izz>
          </inertia>
        </inertial>
        <collision name='chest_link_collision'>
          <pose frame=''>-0.044 0 -0.63 0 -0 0</pose>
          <geometry>
            <mesh>
              <scale>0.001 0.001 0.001</scale>
              <uri>model://cer/meshes/dae/sim_cer_chest.dae</uri>
            </mesh>
          </geometry>
          <max_contacts>10</max_contacts>
          <surface>
            <contact>
              <ode/>
            </contact>
            <bounce/>
            <friction>
              <torsional>
                <ode/>
              </torsional>
              <ode/>
            </friction>
          </surface>
        </collision>
        <visual name='chest_link_visual'>
          <pose frame=''>-0.044 0 -0.63 0 -0 0</pose>
          <geometry>
            <mesh>
              <scale>0.001 0.001 0.001</scale>
              <uri>model://cer/meshes/dae/sim_cer_chest.dae</uri>
            </mesh>
          </geometry>
        </visual>
        <self_collide>0</self_collide>
        <enable_wind>0</enable_wind>
        <kinematic>0</kinematic>
      </link>
      <joint name='torso_yaw_joint' type='revolute'>
        <child>chest_link</child>
        <parent>torso_platform_link</parent>
        <axis>
          <xyz>-0 -0 1</xyz>
          <limit>
            <lower>-1.0472</lower>
            <upper>1.0472</upper>
            <effort>30</effort>
            <velocity>3.14</velocity>
          </limit>
          <dynamics>
            <damping>10</damping>
            <friction>0</friction>
            <spring_reference>0</spring_reference>
            <spring_stiffness>0</spring_stiffness>
          </dynamics>
          <use_parent_model_frame>1</use_parent_model_frame>
        </axis>
        <physics>
          <ode>
            <implicit_spring_damper>1</implicit_spring_damper>
            <cfm_damping>1</cfm_damping>
            <limit>
              <cfm>0</cfm>
              <erp>0.2</erp>
            </limit>
          </ode>
        </physics>
      </joint>
      <link name='l_clavicle_link'>
        <pose frame=''>-0.04 0.177 0.84 0 -0 0</pose>
        <inertial>
          <pose frame=''>0 0 0 0 -0 0</pose>
          <mass>0.2</mass>
          <inertia>
            <ixx>0.000288</ixx>
            <ixy>0</ixy>
            <ixz>0</ixz>
            <iyy>0.000288</iyy>
            <iyz>0</iyz>
            <izz>0.000288</izz>
          </inertia>
        </inertial>
        <collision name='l_clavicle_link_collision'>
          <pose frame=''>0.04 -0.177 -1 0 -0 0</pose>
          <geometry>
            <mesh>
              <scale>0.001 0.001 0.001</scale>
              <uri>model://cer/meshes/dae/sim_cer_l_clavicle.dae</uri>
            </mesh>
          </geometry>
          <max_contacts>10</max_contacts>
          <surface>
            <contact>
              <ode/>
            </contact>
            <bounce/>
            <friction>
              <torsional>
                <ode/>
              </torsional>
              <ode/>
            </friction>
          </surface>
        </collision>
        <visual name='l_clavicle_link_visual'>
          <pose frame=''>0.04 -0.177 -1 0 -0 0</pose>
          <geometry>
            <mesh>
              <scale>0.001 0.001 0.001</scale>
              <uri>model://cer/meshes/dae/sim_cer_l_clavicle.dae</uri>
            </mesh>
          </geometry>
        </visual>
        <self_collide>0</self_collide>
        <enable_wind>0</enable_wind>
        <kinematic>0</kinematic>
      </link>
      <joint name='l_shoulder_pitch_joint' type='revolute'>
        <child>l_clavicle_link</child>
        <parent>chest_link</parent>
        <axis>
          <xyz>0 -0.970296 -0.241922</xyz>
          <limit>
            <lower>-0.523599</lower>
            <upper>1.5708</upper>
            <effort>30</effort>
            <velocity>3.14</velocity>
          </limit>
          <dynamics>
            <damping>10</damping>
            <friction>0</friction>
            <spring_reference>0</spring_reference>
            <spring_stiffness>0</spring_stiffness>
          </dynamics>
          <use_parent_model_frame>1</use_parent_model_frame>
        </axis>
        <physics>
          <ode>
            <implicit_spring_damper>1</implicit_spring_damper>
            <cfm_damping>1</cfm_damping>
            <limit>
              <cfm>0</cfm>
              <erp>0.2</erp>
            </limit>
          </ode>
        </physics>
      </joint>
      <link name='l_shoulder_link'>
        <pose frame=''>-0.04 0.177 0.84 0 -0 0</pose>
        <inertial>
          <pose frame=''>2e-06 0.042148 -0.06332 0 -0 0</pose>
          <mass>0.5</mass>
          <inertia>
            <ixx>0.00076143</ixx>
            <ixy>0</ixy>
            <ixz>-2.84061e-08</ixz>
            <iyy>0.000819748</iyy>
            <iyz>-0.000135828</iyz>
            <izz>0.000588486</izz>
          </inertia>
        </inertial>
        <collision name='l_shoulder_link_collision'>
          <pose frame=''>0.04 -0.177 -1 0 -0 0</pose>
          <geometry>
            <mesh>
              <scale>0.001 0.001 0.001</scale>
              <uri>model://cer/meshes/dae/sim_cer_l_shoulder.dae</uri>
            </mesh>
          </geometry>
          <max_contacts>10</max_contacts>
          <surface>
            <contact>
              <ode/>
            </contact>
            <bounce/>
            <friction>
              <torsional>
                <ode/>
              </torsional>
              <ode/>
            </friction>
          </surface>
        </collision>
        <visual name='l_shoulder_link_visual'>
          <pose frame=''>0.04 -0.177 -1 0 -0 0</pose>
          <geometry>
            <mesh>
              <scale>0.001 0.001 0.001</scale>
              <uri>model://cer/meshes/dae/sim_cer_l_shoulder.dae</uri>
            </mesh>
          </geometry>
        </visual>
        <self_collide>0</self_collide>
        <enable_wind>0</enable_wind>
        <kinematic>0</kinematic>
      </link>
      <joint name='l_shoulder_roll_joint' type='revolute'>
        <child>l_shoulder_link</child>
        <parent>l_clavicle_link</parent>
        <axis>
          <xyz>1 -0 0</xyz>
          <limit>
            <lower>-0.174533</lower>
            <upper>1.309</upper>
            <effort>30</effort>
            <velocity>3.14</velocity>
          </limit>
          <dynamics>
            <damping>10</damping>
            <friction>0</friction>
            <spring_reference>0</spring_reference>
            <spring_stiffness>0</spring_stiffness>
          </dynamics>
          <use_parent_model_frame>1</use_parent_model_frame>
        </axis>
        <physics>
          <ode>
            <implicit_spring_damper>1</implicit_spring_damper>
            <cfm_damping>1</cfm_damping>
            <limit>
              <cfm>0</cfm>
              <erp>0.2</erp>
            </limit>
          </ode>
        </physics>
      </joint>
      <link name='l_upperarm_FT_sensor_link'>
        <pose frame=''>-0.04 0.211 0.73 0 -0 0</pose>
        <inertial>
          <pose frame=''>-0.000784 -0.000123 -0.042763 0 -0 0</pose>
          <mass>0.8</mass>
          <inertia>
            <ixx>0.0012924</ixx>
            <ixy>-4.63196e-08</ixy>
            <ixz>-4.45408e-05</ixz>
            <iyy>0.00128408</iyy>
            <iyz>-1.2213e-06</iyz>
            <izz>0.000657768</izz>
          </inertia>
        </inertial>
        <collision name='l_upperarm_FT_sensor_link_collision'>
          <pose frame=''>0.04 -0.211 -0.89 0 -0 0</pose>
          <geometry>
            <mesh>
              <scale>0.001 0.001 0.001</scale>
              <uri>model://cer/meshes/dae/sim_cer_l_upperarm_sensor.dae</uri>
            </mesh>
          </geometry>
          <max_contacts>10</max_contacts>
          <surface>
            <contact>
              <ode/>
            </contact>
            <bounce/>
            <friction>
              <torsional>
                <ode/>
              </torsional>
              <ode/>
            </friction>
          </surface>
        </collision>
        <collision name='l_upperarm_FT_sensor_link_fixed_joint_lump__l_upperarm_link_collision_1'>
          <pose frame=''>0.04 -0.211 -0.89 0 -0 0</pose>
          <geometry>
            <mesh>
              <scale>0.001 0.001 0.001</scale>
              <uri>model://cer/meshes/dae/sim_cer_l_upperarm.dae</uri>
            </mesh>
          </geometry>
          <max_contacts>10</max_contacts>
          <surface>
            <contact>
              <ode/>
            </contact>
            <bounce/>
            <friction>
              <torsional>
                <ode/>
              </torsional>
              <ode/>
            </friction>
          </surface>
        </collision>
        <visual name='l_upperarm_FT_sensor_link_visual'>
          <pose frame=''>0.04 -0.211 -0.89 0 -0 0</pose>
          <geometry>
            <mesh>
              <scale>0.001 0.001 0.001</scale>
              <uri>model://cer/meshes/dae/sim_cer_l_upperarm_sensor.dae</uri>
            </mesh>
          </geometry>
        </visual>
        <visual name='l_upperarm_FT_sensor_link_fixed_joint_lump__l_upperarm_link_visual_1'>
          <pose frame=''>0.04 -0.211 -0.89 0 -0 0</pose>
          <geometry>
            <mesh>
              <scale>0.001 0.001 0.001</scale>
              <uri>model://cer/meshes/dae/sim_cer_l_upperarm.dae</uri>
            </mesh>
          </geometry>
        </visual>
        <self_collide>0</self_collide>
        <enable_wind>0</enable_wind>
        <kinematic>0</kinematic>
      </link>
      <joint name='l_shoulder_yaw_joint' type='revolute'>
        <child>l_upperarm_FT_sensor_link</child>
        <parent>l_shoulder_link</parent>
        <axis>
          <xyz>-0 -0 1</xyz>
          <limit>
            <lower>-1.5708</lower>
            <upper>1.5708</upper>
            <effort>15</effort>
            <velocity>3.14</velocity>
          </limit>
          <dynamics>
            <damping>10</damping>
            <friction>0</friction>
            <spring_reference>0</spring_reference>
            <spring_stiffness>0</spring_stiffness>
          </dynamics>
          <use_parent_model_frame>1</use_parent_model_frame>
        </axis>
        <physics>
          <ode>
            <implicit_spring_damper>1</implicit_spring_damper>
            <cfm_damping>1</cfm_damping>
            <limit>
              <cfm>0</cfm>
              <erp>0.2</erp>
            </limit>
          </ode>
        </physics>
      </joint>
      <link name='l_elbow_sphere_link'>
        <pose frame=''>-0.04 0.211 0.589 0 -0 0</pose>
        <inertial>
          <pose frame=''>0 0 0 0 -0 0</pose>
          <mass>0.2</mass>
          <inertia>
            <ixx>0.000128</ixx>
            <ixy>0</ixy>
            <ixz>0</ixz>
            <iyy>0.000128</iyy>
            <iyz>0</iyz>
            <izz>0.000128</izz>
          </inertia>
        </inertial>
        <collision name='l_elbow_sphere_link_collision'>
          <pose frame=''>0.04 -0.211 -0.749 0 -0 0</pose>
          <geometry>
            <mesh>
              <scale>0.001 0.001 0.001</scale>
              <uri>model://cer/meshes/dae/sim_cer_l_elbow_sphere.dae</uri>
            </mesh>
          </geometry>
          <max_contacts>10</max_contacts>
          <surface>
            <contact>
              <ode/>
            </contact>
            <bounce/>
            <friction>
              <torsional>
                <ode/>
              </torsional>
              <ode/>
            </friction>
          </surface>
        </collision>
        <visual name='l_elbow_sphere_link_visual'>
          <pose frame=''>0.04 -0.211 -0.749 0 -0 0</pose>
          <geometry>
            <mesh>
              <scale>0.001 0.001 0.001</scale>
              <uri>model://cer/meshes/dae/sim_cer_l_elbow_sphere.dae</uri>
            </mesh>
          </geometry>
        </visual>
        <self_collide>0</self_collide>
        <enable_wind>0</enable_wind>
        <kinematic>0</kinematic>
      </link>
      <joint name='l_elbow_joint' type='revolute'>
        <child>l_elbow_sphere_link</child>
        <parent>l_upperarm_FT_sensor_link</parent>
        <axis>
          <xyz>-0 -1 -0</xyz>
          <limit>
            <lower>0</lower>
            <upper>1.74533</upper>
            <effort>20</effort>
            <velocity>3.14</velocity>
          </limit>
          <dynamics>
            <damping>10</damping>
            <friction>0</friction>
            <spring_reference>0</spring_reference>
            <spring_stiffness>0</spring_stiffness>
          </dynamics>
          <use_parent_model_frame>1</use_parent_model_frame>
        </axis>
        <physics>
          <ode>
            <implicit_spring_damper>1</implicit_spring_damper>
            <cfm_damping>1</cfm_damping>
            <limit>
              <cfm>0</cfm>
              <erp>0.2</erp>
            </limit>
          </ode>
        </physics>
      </joint>
      <link name='l_forearm_link'>
        <pose frame=''>-0.04 0.211 0.518 0 -0 0</pose>
        <inertial>
          <pose frame=''>-0.000512 -0.000175 -0.072511 0 -0 0</pose>
          <mass>0.6</mass>
          <inertia>
            <ixx>0.00283352</ixx>
            <ixy>0</ixy>
            <ixz>3.15449e-05</ixz>
            <iyy>0.00282953</iyy>
            <iyz>1.0379e-07</iyz>
            <izz>0.000436673</izz>
          </inertia>
        </inertial>
        <collision name='l_forearm_link_collision'>
          <pose frame=''>0.04 -0.211 -0.678 0 -0 0</pose>
          <geometry>
            <mesh>
              <scale>0.001 0.001 0.001</scale>
              <uri>model://cer/meshes/dae/sim_cer_l_forearm.dae</uri>
            </mesh>
          </geometry>
          <max_contacts>10</max_contacts>
          <surface>
            <contact>
              <ode/>
            </contact>
            <bounce/>
            <friction>
              <torsional>
                <ode/>
              </torsional>
              <ode/>
            </friction>
          </surface>
        </collision>
        <visual name='l_forearm_link_visual'>
          <pose frame=''>0.04 -0.211 -0.678 0 -0 0</pose>
          <geometry>
            <mesh>
              <scale>0.001 0.001 0.001</scale>
              <uri>model://cer/meshes/dae/sim_cer_l_forearm.dae</uri>
            </mesh>
          </geometry>
        </visual>
        <self_collide>0</self_collide>
        <enable_wind>0</enable_wind>
        <kinematic>0</kinematic>
      </link>
      <joint name='l_wrist_pronosupination_joint' type='revolute'>
        <child>l_forearm_link</child>
        <parent>l_elbow_sphere_link</parent>
        <axis>
          <xyz>0 -0 1</xyz>
          <limit>
            <lower>-1.5708</lower>
            <upper>1.5708</upper>
            <effort>10</effort>
            <velocity>3.14</velocity>
          </limit>
          <dynamics>
            <damping>10</damping>
            <friction>0</friction>
            <spring_reference>0</spring_reference>
            <spring_stiffness>0</spring_stiffness>
          </dynamics>
          <use_parent_model_frame>1</use_parent_model_frame>
        </axis>
        <physics>
          <ode>
            <implicit_spring_damper>1</implicit_spring_damper>
            <cfm_damping>1</cfm_damping>
            <limit>
              <cfm>0</cfm>
              <erp>0.2</erp>
            </limit>
          </ode>
        </physics>
      </joint>
      <link name='l_wrist_slider_eq_link'>
        <pose frame=''>-0.04 0.211 0.589 0 -0 0</pose>
        <inertial>
          <pose frame=''>0 -5.9e-05 -0.225761 0 -0 0</pose>
          <mass>0.3</mass>
          <inertia>
            <ixx>0.000939997</ixx>
            <ixy>0</ixy>
            <ixz>0</ixz>
            <iyy>0.00094</iyy>
            <iyz>4.18243e-09</iyz>
            <izz>0.000220942</izz>
          </inertia>
        </inertial>
        <collision name='l_wrist_slider_eq_link_collision'>
          <pose frame=''>0.04 -0.211 -0.749 0 -0 0</pose>
          <geometry>
            <mesh>
              <scale>0.001 0.001 0.001</scale>
              <uri>model://cer/meshes/dae/sim_cer_l_wrist_slider.dae</uri>
            </mesh>
          </geometry>
          <max_contacts>10</max_contacts>
          <surface>
            <contact>
              <ode/>
            </contact>
            <bounce/>
            <friction>
              <torsional>
                <ode/>
              </torsional>
              <ode/>
            </friction>
          </surface>
        </collision>
        <visual name='l_wrist_slider_eq_link_visual'>
          <pose frame=''>0.04 -0.211 -0.749 0 -0 0</pose>
          <geometry>
            <mesh>
              <scale>0.001 0.001 0.001</scale>
              <uri>model://cer/meshes/dae/sim_cer_l_wrist_slider.dae</uri>
            </mesh>
          </geometry>
        </visual>
        <self_collide>0</self_collide>
        <enable_wind>0</enable_wind>
        <kinematic>0</kinematic>
      </link>
      <joint name='l_wrist_heave_eq_joint' type='prismatic'>
        <child>l_wrist_slider_eq_link</child>
        <parent>l_forearm_link</parent>
        <axis>
          <xyz>-0 0 -1</xyz>
          <limit>
            <lower>0</lower>
            <upper>0.13</upper>
            <effort>200</effort>
            <velocity>0.25</velocity>
          </limit>
          <dynamics>
            <damping>100</damping>
            <friction>0</friction>
            <spring_reference>0</spring_reference>
            <spring_stiffness>0</spring_stiffness>
          </dynamics>
          <use_parent_model_frame>1</use_parent_model_frame>
        </axis>
        <physics>
          <ode>
            <implicit_spring_damper>1</implicit_spring_damper>
            <cfm_damping>1</cfm_damping>
            <limit>
              <cfm>0</cfm>
              <erp>0.2</erp>
            </limit>
          </ode>
        </physics>
      </joint>
      <link name='l_wrist_cup_eq_link'>
        <pose frame=''>-0.072 0.211 0.298 0 -0 0</pose>
        <inertial>
          <pose frame=''>0.031989 -5.9e-05 -0.018146 0 -0 0</pose>
          <mass>0.2</mass>
          <inertia>
            <ixx>0.000102239</ixx>
            <ixy>0</ixy>
            <ixz>3.78925e-08</ixz>
            <iyy>0.000102239</iyy>
            <iyz>0</iyz>
            <izz>0.000163555</izz>
          </inertia>
        </inertial>
        <collision name='l_wrist_cup_eq_link_collision'>
          <pose frame=''>0.072 -0.211 -0.458 0 -0 0</pose>
          <geometry>
            <mesh>
              <scale>0.001 0.001 0.001</scale>
              <uri>model://cer/meshes/dae/sim_cer_l_wrist_cup_eq.dae</uri>
            </mesh>
          </geometry>
          <max_contacts>10</max_contacts>
          <surface>
            <contact>
              <ode/>
            </contact>
            <bounce/>
            <friction>
              <torsional>
                <ode/>
              </torsional>
              <ode/>
            </friction>
          </surface>
        </collision>
        <visual name='l_wrist_cup_eq_link_visual'>
          <pose frame=''>0.072 -0.211 -0.458 0 -0 0</pose>
          <geometry>
            <mesh>
              <scale>0.001 0.001 0.001</scale>
              <uri>model://cer/meshes/dae/sim_cer_l_wrist_cup_eq.dae</uri>
            </mesh>
          </geometry>
        </visual>
        <self_collide>0</self_collide>
        <enable_wind>0</enable_wind>
        <kinematic>0</kinematic>
      </link>
      <joint name='l_wrist_roll_eq_joint' type='revolute'>
        <child>l_wrist_cup_eq_link</child>
        <parent>l_wrist_slider_eq_link</parent>
        <axis>
          <xyz>1 0 -0</xyz>
          <limit>
            <lower>-0.523599</lower>
            <upper>0.523599</upper>
            <effort>10</effort>
            <velocity>3.14</velocity>
          </limit>
          <dynamics>
            <damping>10</damping>
            <friction>0</friction>
            <spring_reference>0</spring_reference>
            <spring_stiffness>0</spring_stiffness>
          </dynamics>
          <use_parent_model_frame>1</use_parent_model_frame>
        </axis>
        <physics>
          <ode>
            <implicit_spring_damper>1</implicit_spring_damper>
            <cfm_damping>1</cfm_damping>
            <limit>
              <cfm>0</cfm>
              <erp>0.2</erp>
            </limit>
          </ode>
        </physics>
      </joint>
      <link name='l_hand_root_link'>
        <pose frame=''>-0.04 0.211 0.298 0 -0 0</pose>
        <inertial>
          <pose frame=''>0.000191 -0.013614 -0.06234 0 -0 0</pose>
          <mass>0.3</mass>
          <inertia>
            <ixx>0.000294522</ixx>
            <ixy>1.41029e-06</ixy>
            <ixz>6.92026e-08</ixz>
            <iyy>0.000297775</iyy>
            <iyz>-2.11461e-05</iyz>
            <izz>0.000189897</izz>
          </inertia>
        </inertial>
        <collision name='l_hand_root_link_collision'>
          <pose frame=''>0.04 -0.211 -0.458 0 -0 0</pose>
          <geometry>
            <mesh>
              <scale>0.001 0.001 0.001</scale>
              <uri>model://cer/meshes/dae/sim_cer_l_hand_root.dae</uri>
            </mesh>
          </geometry>
          <max_contacts>10</max_contacts>
          <surface>
            <contact>
              <ode/>
            </contact>
            <bounce/>
            <friction>
              <torsional>
                <ode/>
              </torsional>
              <ode/>
            </friction>
          </surface>
        </collision>
        <visual name='l_hand_root_link_visual'>
          <pose frame=''>0.04 -0.211 -0.458 0 -0 0</pose>
          <geometry>
            <mesh>
              <scale>0.001 0.001 0.001</scale>
              <uri>model://cer/meshes/dae/sim_cer_l_hand_root.dae</uri>
            </mesh>
          </geometry>
        </visual>
        <self_collide>0</self_collide>
        <enable_wind>0</enable_wind>
        <kinematic>0</kinematic>
      </link>
      <joint name='l_wrist_pitch_eq_joint' type='revolute'>
        <child>l_hand_root_link</child>
        <parent>l_wrist_cup_eq_link</parent>
        <axis>
          <xyz>-0 -1 -0</xyz>
          <limit>
            <lower>-0.523599</lower>
            <upper>0.523599</upper>
            <effort>10</effort>
            <velocity>3.14</velocity>
          </limit>
          <dynamics>
            <damping>10</damping>
            <friction>0</friction>
            <spring_reference>0</spring_reference>
            <spring_stiffness>0</spring_stiffness>
          </dynamics>
          <use_parent_model_frame>1</use_parent_model_frame>
        </axis>
        <physics>
          <ode>
            <implicit_spring_damper>1</implicit_spring_damper>
            <cfm_damping>1</cfm_damping>
            <limit>
              <cfm>0</cfm>
              <erp>0.2</erp>
            </limit>
          </ode>
        </physics>
      </joint>
      <link name='l_hand_paddle_proximal_link'>
        <pose frame=''>-0.04 0.198143 0.185494 0 -0 0</pose>
        <inertial>
          <pose frame=''>-9.7e-05 0.010867 -0.022259 0 -0 0</pose>
          <mass>0.05</mass>
          <inertia>
            <ixx>0.0001</ixx>
            <ixy>-6.9439e-09</ixy>
            <ixz>1.7549e-08</ixz>
            <iyy>0.0001</iyy>
            <iyz>1.81902e-06</iyz>
            <izz>0.0001</izz>
          </inertia>
        </inertial>
        <collision name='l_hand_paddle_proximal_link_collision'>
          <pose frame=''>0.04 -0.198143 -0.345494 0 -0 0</pose>
          <geometry>
            <mesh>
              <scale>0.001 0.001 0.001</scale>
              <uri>model://cer/meshes/dae/sim_cer_l_hand_paddle_proximal.dae</uri>
            </mesh>
          </geometry>
          <max_contacts>10</max_contacts>
          <surface>
            <contact>
              <ode/>
            </contact>
            <bounce/>
            <friction>
              <torsional>
                <ode/>
              </torsional>
              <ode/>
            </friction>
          </surface>
        </collision>
        <visual name='l_hand_paddle_proximal_link_visual'>
          <pose frame=''>0.04 -0.198143 -0.345494 0 -0 0</pose>
          <geometry>
            <mesh>
              <scale>0.001 0.001 0.001</scale>
              <uri>model://cer/meshes/dae/sim_cer_l_hand_paddle_proximal.dae</uri>
            </mesh>
          </geometry>
        </visual>
        <self_collide>0</self_collide>
        <enable_wind>0</enable_wind>
        <kinematic>0</kinematic>
      </link>
      <joint name='l_hand_paddle_proximal_joint' type='revolute'>
        <child>l_hand_paddle_proximal_link</child>
        <parent>l_hand_root_link</parent>
        <axis>
          <xyz>-1 -0 0</xyz>
          <limit>
            <lower>0</lower>
            <upper>1.22173</upper>
            <effort>5</effort>
            <velocity>3.14</velocity>
          </limit>
          <dynamics>
            <damping>10</damping>
            <friction>0</friction>
            <spring_reference>0</spring_reference>
            <spring_stiffness>0</spring_stiffness>
          </dynamics>
          <use_parent_model_frame>1</use_parent_model_frame>
        </axis>
        <physics>
          <ode>
            <implicit_spring_damper>1</implicit_spring_damper>
            <cfm_damping>1</cfm_damping>
            <limit>
              <cfm>0</cfm>
              <erp>0.2</erp>
            </limit>
          </ode>
        </physics>
      </joint>
      <link name='l_hand_paddle_distal_link'>
        <pose frame=''>-0.04 0.214471 0.146748 0 -0 0</pose>
        <inertial>
          <pose frame=''>0.001321 0.005592 -0.020601 0 -0 0</pose>
          <mass>0.05</mass>
          <inertia>
            <ixx>0.0001</ixx>
            <ixy>-1.94983e-07</ixy>
            <ixz>9.01259e-07</ixz>
            <iyy>0.0001</iyy>
            <iyz>6.79853e-07</iyz>
            <izz>0.0001</izz>
          </inertia>
        </inertial>
        <collision name='l_hand_paddle_distal_link_collision'>
          <pose frame=''>0.04 -0.214471 -0.306748 0 -0 0</pose>
          <geometry>
            <mesh>
              <scale>0.001 0.001 0.001</scale>
              <uri>model://cer/meshes/dae/sim_cer_l_hand_paddle_distal.dae</uri>
            </mesh>
          </geometry>
          <max_contacts>10</max_contacts>
          <surface>
            <contact>
              <ode/>
            </contact>
            <bounce/>
            <friction>
              <torsional>
                <ode/>
              </torsional>
              <ode/>
            </friction>
          </surface>
        </collision>
        <visual name='l_hand_paddle_distal_link_visual'>
          <pose frame=''>0.04 -0.214471 -0.306748 0 -0 0</pose>
          <geometry>
            <mesh>
              <scale>0.001 0.001 0.001</scale>
              <uri>model://cer/meshes/dae/sim_cer_l_hand_paddle_distal.dae</uri>
            </mesh>
          </geometry>
        </visual>
        <self_collide>0</self_collide>
        <enable_wind>0</enable_wind>
        <kinematic>0</kinematic>
      </link>
      <joint name='l_hand_paddle_distal_joint' type='revolute'>
        <child>l_hand_paddle_distal_link</child>
        <parent>l_hand_paddle_proximal_link</parent>
        <axis>
          <xyz>-1 -0 0</xyz>
          <limit>
            <lower>0</lower>
            <upper>1.22173</upper>
            <effort>5</effort>
            <velocity>3.14</velocity>
          </limit>
          <dynamics>
            <damping>10</damping>
            <friction>0</friction>
            <spring_reference>0</spring_reference>
            <spring_stiffness>0</spring_stiffness>
          </dynamics>
          <use_parent_model_frame>1</use_parent_model_frame>
        </axis>
        <physics>
          <ode>
            <implicit_spring_damper>1</implicit_spring_damper>
            <cfm_damping>1</cfm_damping>
            <limit>
              <cfm>0</cfm>
              <erp>0.2</erp>
            </limit>
          </ode>
        </physics>
      </joint>
      <link name='l_hand_thumb_proximal_link'>
        <pose frame=''>-0.04 0.171352 0.222282 0 -0 0</pose>
        <inertial>
          <pose frame=''>0.002515 -0.017936 -0.003159 0 -0 0</pose>
          <mass>0.05</mass>
          <inertia>
            <ixx>0.0001</ixx>
            <ixy>-1.50858e-09</ixy>
            <ixz>3.04948e-10</ixz>
            <iyy>0.0001</iyy>
            <iyz>-2.63475e-06</iyz>
            <izz>0.0001</izz>
          </inertia>
        </inertial>
        <collision name='l_hand_thumb_proximal_link_collision'>
          <pose frame=''>0.04 -0.171352 -0.382282 0 -0 0</pose>
          <geometry>
            <mesh>
              <scale>0.001 0.001 0.001</scale>
              <uri>model://cer/meshes/dae/sim_cer_l_hand_thumb_proximal.dae</uri>
            </mesh>
          </geometry>
          <max_contacts>10</max_contacts>
          <surface>
            <contact>
              <ode/>
            </contact>
            <bounce/>
            <friction>
              <torsional>
                <ode/>
              </torsional>
              <ode/>
            </friction>
          </surface>
        </collision>
        <visual name='l_hand_thumb_proximal_link_visual'>
          <pose frame=''>0.04 -0.171352 -0.382282 0 -0 0</pose>
          <geometry>
            <mesh>
              <scale>0.001 0.001 0.001</scale>
              <uri>model://cer/meshes/dae/sim_cer_l_hand_thumb_proximal.dae</uri>
            </mesh>
          </geometry>
        </visual>
        <self_collide>0</self_collide>
        <enable_wind>0</enable_wind>
        <kinematic>0</kinematic>
      </link>
      <joint name='l_hand_thumb_proximal_joint' type='revolute'>
        <child>l_hand_thumb_proximal_link</child>
        <parent>l_hand_root_link</parent>
        <axis>
          <xyz>1 0 -0</xyz>
          <limit>
            <lower>0</lower>
            <upper>1.0472</upper>
            <effort>5</effort>
            <velocity>3.14</velocity>
          </limit>
          <dynamics>
            <damping>10</damping>
            <friction>0</friction>
            <spring_reference>0</spring_reference>
            <spring_stiffness>0</spring_stiffness>
          </dynamics>
          <use_parent_model_frame>1</use_parent_model_frame>
        </axis>
        <physics>
          <ode>
            <implicit_spring_damper>1</implicit_spring_damper>
            <cfm_damping>1</cfm_damping>
            <limit>
              <cfm>0</cfm>
              <erp>0.2</erp>
            </limit>
          </ode>
        </physics>
      </joint>
      <link name='l_hand_thumb_distal_link'>
        <pose frame=''>-0.039745 0.130827 0.211296 0 -0 0</pose>
        <inertial>
          <pose frame=''>0.002193 -0.014529 -0.005865 0 -0 0</pose>
          <mass>0.05</mass>
          <inertia>
            <ixx>0.0001</ixx>
            <ixy>1.50893e-10</ixy>
            <ixz>4.0488e-10</ixz>
            <iyy>0.0001</iyy>
            <iyz>-9.14021e-07</iyz>
            <izz>0.0001</izz>
          </inertia>
        </inertial>
        <collision name='l_hand_thumb_distal_link_collision'>
          <pose frame=''>0.039745 -0.130827 -0.371296 0 -0 0</pose>
          <geometry>
            <mesh>
              <scale>0.001 0.001 0.001</scale>
              <uri>model://cer/meshes/dae/sim_cer_l_hand_thumb_distal.dae</uri>
            </mesh>
          </geometry>
          <max_contacts>10</max_contacts>
          <surface>
            <contact>
              <ode/>
            </contact>
            <bounce/>
            <friction>
              <torsional>
                <ode/>
              </torsional>
              <ode/>
            </friction>
          </surface>
        </collision>
        <visual name='l_hand_thumb_distal_link_visual'>
          <pose frame=''>0.039745 -0.130827 -0.371296 0 -0 0</pose>
          <geometry>
            <mesh>
              <scale>0.001 0.001 0.001</scale>
              <uri>model://cer/meshes/dae/sim_cer_l_hand_thumb_distal.dae</uri>
            </mesh>
          </geometry>
        </visual>
        <self_collide>0</self_collide>
        <enable_wind>0</enable_wind>
        <kinematic>0</kinematic>
      </link>
      <joint name='l_hand_thumb_distal_joint' type='revolute'>
        <child>l_hand_thumb_distal_link</child>
        <parent>l_hand_thumb_proximal_link</parent>
        <axis>
          <xyz>1 0 -0</xyz>
          <limit>
            <lower>0</lower>
            <upper>1.22173</upper>
            <effort>5</effort>
            <velocity>3.14</velocity>
          </limit>
          <dynamics>
            <damping>10</damping>
            <friction>0</friction>
            <spring_reference>0</spring_reference>
            <spring_stiffness>0</spring_stiffness>
          </dynamics>
          <use_parent_model_frame>1</use_parent_model_frame>
        </axis>
        <physics>
          <ode>
            <implicit_spring_damper>1</implicit_spring_damper>
            <cfm_damping>1</cfm_damping>
            <limit>
              <cfm>0</cfm>
              <erp>0.2</erp>
            </limit>
          </ode>
        </physics>
      </joint>
      <link name='neck_link'>
        <pose frame=''>-0.05 -0 0.87 0 -0 0</pose>
        <inertial>
          <pose frame=''>-0.000322 0 0.07756 0 -0 0</pose>
          <mass>1.4</mass>
          <inertia>
            <ixx>0.00429793</ixx>
            <ixy>0</ixy>
            <ixz>-0.000592817</ixz>
            <iyy>0.00443784</iyy>
            <iyz>-6.85477e-08</iyz>
            <izz>0.000419904</izz>
          </inertia>
        </inertial>
        <collision name='neck_link_collision'>
          <pose frame=''>0.05 0 -1.03 0 -0 0</pose>
          <geometry>
            <mesh>
              <scale>0.001 0.001 0.001</scale>
              <uri>model://cer/meshes/dae/sim_cer_neck.dae</uri>
            </mesh>
          </geometry>
          <max_contacts>10</max_contacts>
          <surface>
            <contact>
              <ode/>
            </contact>
            <bounce/>
            <friction>
              <torsional>
                <ode/>
              </torsional>
              <ode/>
            </friction>
          </surface>
        </collision>
        <visual name='neck_link_visual'>
          <pose frame=''>0.05 0 -1.03 0 -0 0</pose>
          <geometry>
            <mesh>
              <scale>0.001 0.001 0.001</scale>
              <uri>model://cer/meshes/dae/sim_cer_neck.dae</uri>
            </mesh>
          </geometry>
        </visual>
        <self_collide>0</self_collide>
        <enable_wind>0</enable_wind>
        <kinematic>0</kinematic>
      </link>
      <joint name='neck_pitch_joint' type='revolute'>
        <child>neck_link</child>
        <parent>chest_link</parent>
        <axis>
          <xyz>0 1 0</xyz>
          <limit>
            <lower>-0.523599</lower>
            <upper>0.872665</upper>
            <effort>10</effort>
            <velocity>3.14</velocity>
          </limit>
          <dynamics>
            <damping>10</damping>
            <friction>0</friction>
            <spring_reference>0</spring_reference>
            <spring_stiffness>0</spring_stiffness>
          </dynamics>
          <use_parent_model_frame>1</use_parent_model_frame>
        </axis>
        <physics>
          <ode>
            <implicit_spring_damper>1</implicit_spring_damper>
            <cfm_damping>1</cfm_damping>
            <limit>
              <cfm>0</cfm>
              <erp>0.2</erp>
            </limit>
          </ode>
        </physics>
      </joint>
      <link name='head_link'>
        <pose frame=''>-0.038321 -0 1.02838 0 -0 0</pose>
        <inertial>
          <pose frame=''>0.030149 -2e-06 -0.00035 0 -0 0</pose>
          <mass>2</mass>
          <inertia>
            <ixx>0.0106536</ixx>
            <ixy>-7.34817e-08</ixy>
            <ixz>0.000274098</ixz>
            <iyy>0.00398482</iyy>
            <iyz>1.64063e-07</iyz>
            <izz>0.00944369</izz>
          </inertia>
        </inertial>
        <collision name='head_link_collision'>
          <pose frame=''>0.038321 0 -1.18838 0 -0 0</pose>
          <geometry>
            <mesh>
              <scale>0.001 0.001 0.001</scale>
              <uri>model://cer/meshes/dae/sim_cer_head.dae</uri>
            </mesh>
          </geometry>
          <surface>
            <contact>
              <ode/>
            </contact>
            <friction>
              <ode/>
              <torsional>
                <ode/>
              </torsional>
            </friction>
            <bounce/>
          </surface>
          <max_contacts>10</max_contacts>
        </collision>
        <visual name='head_link_visual'>
          <pose frame=''>0.038321 0 -1.18838 0 -0 0</pose>
          <geometry>
            <mesh>
              <scale>0.001 0.001 0.001</scale>
              <uri>model://cer/meshes/dae/sim_cer_head.dae</uri>
            </mesh>
          </geometry>
          <material>
            <diffuse>1 1 1 1</diffuse>
            <script>
              <uri>__default__</uri>
              <name>__default__</name>
            </script>
          </material>
          <plugin name='face' filename='libgazebo_yarp_videotexture.so'>
            <yarpConfigurationFile>model://cer/conf/sim_cer_face.ini</yarpConfigurationFile>
          </plugin>
        </visual>
        <self_collide>0</self_collide>
        <enable_wind>0</enable_wind>
        <kinematic>0</kinematic>
      </link>
      <joint name='neck_yaw_joint' type='revolute'>
        <child>head_link</child>
        <parent>neck_link</parent>
        <axis>
          <xyz>0.173648 -0 0.984808</xyz>
          <limit>
            <lower>-1.39626</lower>
            <upper>1.39626</upper>
            <effort>10</effort>
            <velocity>3.14</velocity>
          </limit>
          <dynamics>
            <damping>10</damping>
            <friction>0</friction>
            <spring_reference>0</spring_reference>
            <spring_stiffness>0</spring_stiffness>
          </dynamics>
          <use_parent_model_frame>1</use_parent_model_frame>
        </axis>
        <physics>
          <ode>
            <implicit_spring_damper>1</implicit_spring_damper>
            <cfm_damping>1</cfm_damping>
            <limit>
              <cfm>0</cfm>
              <erp>0.2</erp>
            </limit>
          </ode>
        </physics>
      </joint>
      <link name='r_clavicle_link'>
        <pose frame=''>-0.04 -0.177 0.84 0 -0 0</pose>
        <inertial>
          <pose frame=''>0 0 0 0 -0 0</pose>
          <mass>0.2</mass>
          <inertia>
            <ixx>0.000288</ixx>
            <ixy>0</ixy>
            <ixz>0</ixz>
            <iyy>0.000288</iyy>
            <iyz>0</iyz>
            <izz>0.000288</izz>
          </inertia>
        </inertial>
        <collision name='r_clavicle_link_collision'>
          <pose frame=''>0.04 0.177 -1 0 -0 0</pose>
          <geometry>
            <mesh>
              <scale>0.001 0.001 0.001</scale>
              <uri>model://cer/meshes/dae/sim_cer_r_clavicle.dae</uri>
            </mesh>
          </geometry>
          <max_contacts>10</max_contacts>
          <surface>
            <contact>
              <ode/>
            </contact>
            <bounce/>
            <friction>
              <torsional>
                <ode/>
              </torsional>
              <ode/>
            </friction>
          </surface>
        </collision>
        <visual name='r_clavicle_link_visual'>
          <pose frame=''>0.04 0.177 -1 0 -0 0</pose>
          <geometry>
            <mesh>
              <scale>0.001 0.001 0.001</scale>
              <uri>model://cer/meshes/dae/sim_cer_r_clavicle.dae</uri>
            </mesh>
          </geometry>
        </visual>
        <self_collide>0</self_collide>
        <enable_wind>0</enable_wind>
        <kinematic>0</kinematic>
      </link>
      <joint name='r_shoulder_pitch_joint' type='revolute'>
        <child>r_clavicle_link</child>
        <parent>chest_link</parent>
        <axis>
          <xyz>-0 -0.970296 0.241922</xyz>
          <limit>
            <lower>-0.523599</lower>
            <upper>1.5708</upper>
            <effort>30</effort>
            <velocity>3.14</velocity>
          </limit>
          <dynamics>
            <damping>10</damping>
            <friction>0</friction>
            <spring_reference>0</spring_reference>
            <spring_stiffness>0</spring_stiffness>
          </dynamics>
          <use_parent_model_frame>1</use_parent_model_frame>
        </axis>
        <physics>
          <ode>
            <implicit_spring_damper>1</implicit_spring_damper>
            <cfm_damping>1</cfm_damping>
            <limit>
              <cfm>0</cfm>
              <erp>0.2</erp>
            </limit>
          </ode>
        </physics>
      </joint>
      <link name='r_shoulder_link'>
        <pose frame=''>-0.04 -0.177 0.84 0 -0 0</pose>
        <inertial>
          <pose frame=''>2e-06 -0.042148 -0.06332 0 -0 0</pose>
          <mass>0.5</mass>
          <inertia>
            <ixx>0.00076143</ixx>
            <ixy>0</ixy>
            <ixz>-2.84508e-08</ixz>
            <iyy>0.000819748</iyy>
            <iyz>0.000135828</iyz>
            <izz>0.000588486</izz>
          </inertia>
        </inertial>
        <collision name='r_shoulder_link_collision'>
          <pose frame=''>0.04 0.177 -1 0 -0 0</pose>
          <geometry>
            <mesh>
              <scale>0.001 0.001 0.001</scale>
              <uri>model://cer/meshes/dae/sim_cer_r_shoulder.dae</uri>
            </mesh>
          </geometry>
          <max_contacts>10</max_contacts>
          <surface>
            <contact>
              <ode/>
            </contact>
            <bounce/>
            <friction>
              <torsional>
                <ode/>
              </torsional>
              <ode/>
            </friction>
          </surface>
        </collision>
        <visual name='r_shoulder_link_visual'>
          <pose frame=''>0.04 0.177 -1 0 -0 0</pose>
          <geometry>
            <mesh>
              <scale>0.001 0.001 0.001</scale>
              <uri>model://cer/meshes/dae/sim_cer_r_shoulder.dae</uri>
            </mesh>
          </geometry>
        </visual>
        <self_collide>0</self_collide>
        <enable_wind>0</enable_wind>
        <kinematic>0</kinematic>
      </link>
      <joint name='r_shoulder_roll_joint' type='revolute'>
        <child>r_shoulder_link</child>
        <parent>r_clavicle_link</parent>
        <axis>
          <xyz>-1 0 0</xyz>
          <limit>
            <lower>-0.174533</lower>
            <upper>1.309</upper>
            <effort>30</effort>
            <velocity>3.14</velocity>
          </limit>
          <dynamics>
            <damping>10</damping>
            <friction>0</friction>
            <spring_reference>0</spring_reference>
            <spring_stiffness>0</spring_stiffness>
          </dynamics>
          <use_parent_model_frame>1</use_parent_model_frame>
        </axis>
        <physics>
          <ode>
            <implicit_spring_damper>1</implicit_spring_damper>
            <cfm_damping>1</cfm_damping>
            <limit>
              <cfm>0</cfm>
              <erp>0.2</erp>
            </limit>
          </ode>
        </physics>
      </joint>
      <link name='r_upperarm_FT_sensor_link'>
        <pose frame=''>-0.04 -0.211 0.73 0 -0 0</pose>
        <inertial>
          <pose frame=''>-0.000784 0.000123 -0.042763 0 -0 0</pose>
          <mass>0.8</mass>
          <inertia>
            <ixx>0.0012924</ixx>
            <ixy>4.63196e-08</ixy>
            <ixz>-4.45409e-05</ixz>
            <iyy>0.00128408</iyy>
            <iyz>1.2212e-06</iyz>
            <izz>0.000657768</izz>
          </inertia>
        </inertial>
        <collision name='r_upperarm_FT_sensor_link_collision'>
          <pose frame=''>0.04 0.211 -0.89 0 -0 0</pose>
          <geometry>
            <mesh>
              <scale>0.001 0.001 0.001</scale>
              <uri>model://cer/meshes/dae/sim_cer_r_upperarm_sensor.dae</uri>
            </mesh>
          </geometry>
          <max_contacts>10</max_contacts>
          <surface>
            <contact>
              <ode/>
            </contact>
            <bounce/>
            <friction>
              <torsional>
                <ode/>
              </torsional>
              <ode/>
            </friction>
          </surface>
        </collision>
        <collision name='r_upperarm_FT_sensor_link_fixed_joint_lump__r_upperarm_link_collision_1'>
          <pose frame=''>0.04 0.211 -0.89 0 -0 0</pose>
          <geometry>
            <mesh>
              <scale>0.001 0.001 0.001</scale>
              <uri>model://cer/meshes/dae/sim_cer_r_upperarm.dae</uri>
            </mesh>
          </geometry>
          <max_contacts>10</max_contacts>
          <surface>
            <contact>
              <ode/>
            </contact>
            <bounce/>
            <friction>
              <torsional>
                <ode/>
              </torsional>
              <ode/>
            </friction>
          </surface>
        </collision>
        <visual name='r_upperarm_FT_sensor_link_visual'>
          <pose frame=''>0.04 0.211 -0.89 0 -0 0</pose>
          <geometry>
            <mesh>
              <scale>0.001 0.001 0.001</scale>
              <uri>model://cer/meshes/dae/sim_cer_r_upperarm_sensor.dae</uri>
            </mesh>
          </geometry>
        </visual>
        <visual name='r_upperarm_FT_sensor_link_fixed_joint_lump__r_upperarm_link_visual_1'>
          <pose frame=''>0.04 0.211 -0.89 0 -0 0</pose>
          <geometry>
            <mesh>
              <scale>0.001 0.001 0.001</scale>
              <uri>model://cer/meshes/dae/sim_cer_r_upperarm.dae</uri>
            </mesh>
          </geometry>
        </visual>
        <self_collide>0</self_collide>
        <enable_wind>0</enable_wind>
        <kinematic>0</kinematic>
      </link>
      <joint name='r_shoulder_yaw_joint' type='revolute'>
        <child>r_upperarm_FT_sensor_link</child>
        <parent>r_shoulder_link</parent>
        <axis>
          <xyz>0 0 -1</xyz>
          <limit>
            <lower>-1.5708</lower>
            <upper>1.5708</upper>
            <effort>15</effort>
            <velocity>3.14</velocity>
          </limit>
          <dynamics>
            <damping>10</damping>
            <friction>0</friction>
            <spring_reference>0</spring_reference>
            <spring_stiffness>0</spring_stiffness>
          </dynamics>
          <use_parent_model_frame>1</use_parent_model_frame>
        </axis>
        <physics>
          <ode>
            <implicit_spring_damper>1</implicit_spring_damper>
            <cfm_damping>1</cfm_damping>
            <limit>
              <cfm>0</cfm>
              <erp>0.2</erp>
            </limit>
          </ode>
        </physics>
      </joint>
      <link name='r_elbow_sphere_link'>
        <pose frame=''>-0.04 -0.211 0.589 0 -0 0</pose>
        <inertial>
          <pose frame=''>0 0 0 0 -0 0</pose>
          <mass>0.2</mass>
          <inertia>
            <ixx>0.000128</ixx>
            <ixy>0</ixy>
            <ixz>0</ixz>
            <iyy>0.000128</iyy>
            <iyz>0</iyz>
            <izz>0.000128</izz>
          </inertia>
        </inertial>
        <collision name='r_elbow_sphere_link_collision'>
          <pose frame=''>0.04 0.211 -0.749 0 -0 0</pose>
          <geometry>
            <mesh>
              <scale>0.001 0.001 0.001</scale>
              <uri>model://cer/meshes/dae/sim_cer_r_elbow_sphere.dae</uri>
            </mesh>
          </geometry>
          <max_contacts>10</max_contacts>
          <surface>
            <contact>
              <ode/>
            </contact>
            <bounce/>
            <friction>
              <torsional>
                <ode/>
              </torsional>
              <ode/>
            </friction>
          </surface>
        </collision>
        <visual name='r_elbow_sphere_link_visual'>
          <pose frame=''>0.04 0.211 -0.749 0 -0 0</pose>
          <geometry>
            <mesh>
              <scale>0.001 0.001 0.001</scale>
              <uri>model://cer/meshes/dae/sim_cer_r_elbow_sphere.dae</uri>
            </mesh>
          </geometry>
        </visual>
        <self_collide>0</self_collide>
        <enable_wind>0</enable_wind>
        <kinematic>0</kinematic>
      </link>
      <joint name='r_elbow_joint' type='revolute'>
        <child>r_elbow_sphere_link</child>
        <parent>r_upperarm_FT_sensor_link</parent>
        <axis>
          <xyz>-0 -1 -0</xyz>
          <limit>
            <lower>0</lower>
            <upper>1.74533</upper>
            <effort>20</effort>
            <velocity>3.14</velocity>
          </limit>
          <dynamics>
            <damping>10</damping>
            <friction>0</friction>
            <spring_reference>0</spring_reference>
            <spring_stiffness>0</spring_stiffness>
          </dynamics>
          <use_parent_model_frame>1</use_parent_model_frame>
        </axis>
        <physics>
          <ode>
            <implicit_spring_damper>1</implicit_spring_damper>
            <cfm_damping>1</cfm_damping>
            <limit>
              <cfm>0</cfm>
              <erp>0.2</erp>
            </limit>
          </ode>
        </physics>
      </joint>
      <link name='r_forearm_link'>
        <pose frame=''>-0.04 -0.211 0.518 0 -0 0</pose>
        <inertial>
          <pose frame=''>-0.000512 0.000175 -0.072511 0 -0 0</pose>
          <mass>0.6</mass>
          <inertia>
            <ixx>0.00283352</ixx>
            <ixy>0</ixy>
            <ixz>3.15449e-05</ixz>
            <iyy>0.00282953</iyy>
            <iyz>-1.03787e-07</iyz>
            <izz>0.000436673</izz>
          </inertia>
        </inertial>
        <collision name='r_forearm_link_collision'>
          <pose frame=''>0.04 0.211 -0.678 0 -0 0</pose>
          <geometry>
            <mesh>
              <scale>0.001 0.001 0.001</scale>
              <uri>model://cer/meshes/dae/sim_cer_r_forearm.dae</uri>
            </mesh>
          </geometry>
          <max_contacts>10</max_contacts>
          <surface>
            <contact>
              <ode/>
            </contact>
            <bounce/>
            <friction>
              <torsional>
                <ode/>
              </torsional>
              <ode/>
            </friction>
          </surface>
        </collision>
        <visual name='r_forearm_link_visual'>
          <pose frame=''>0.04 0.211 -0.678 0 -0 0</pose>
          <geometry>
            <mesh>
              <scale>0.001 0.001 0.001</scale>
              <uri>model://cer/meshes/dae/sim_cer_r_forearm.dae</uri>
            </mesh>
          </geometry>
        </visual>
        <self_collide>0</self_collide>
        <enable_wind>0</enable_wind>
        <kinematic>0</kinematic>
      </link>
      <joint name='r_wrist_pronosupination_joint' type='revolute'>
        <child>r_forearm_link</child>
        <parent>r_elbow_sphere_link</parent>
        <axis>
          <xyz>-0 0 -1</xyz>
          <limit>
            <lower>-1.5708</lower>
            <upper>1.5708</upper>
            <effort>10</effort>
            <velocity>3.14</velocity>
          </limit>
          <dynamics>
            <damping>10</damping>
            <friction>0</friction>
            <spring_reference>0</spring_reference>
            <spring_stiffness>0</spring_stiffness>
          </dynamics>
          <use_parent_model_frame>1</use_parent_model_frame>
        </axis>
        <physics>
          <ode>
            <implicit_spring_damper>1</implicit_spring_damper>
            <cfm_damping>1</cfm_damping>
            <limit>
              <cfm>0</cfm>
              <erp>0.2</erp>
            </limit>
          </ode>
        </physics>
      </joint>
      <link name='r_wrist_slider_eq_link'>
        <pose frame=''>-0.04 -0.211 0.589 0 -0 0</pose>
        <inertial>
          <pose frame=''>0 5.9e-05 -0.225759 0 -0 0</pose>
          <mass>0.3</mass>
          <inertia>
            <ixx>0.00094001</ixx>
            <ixy>0</ixy>
            <ixz>0</ixz>
            <iyy>0.000940012</iyy>
            <iyz>0</iyz>
            <izz>0.00022094</izz>
          </inertia>
        </inertial>
        <collision name='r_wrist_slider_eq_link_collision'>
          <pose frame=''>0.04 0.211 -0.749 0 -0 0</pose>
          <geometry>
            <mesh>
              <scale>0.001 0.001 0.001</scale>
              <uri>model://cer/meshes/dae/sim_cer_r_wrist_slider.dae</uri>
            </mesh>
          </geometry>
          <max_contacts>10</max_contacts>
          <surface>
            <contact>
              <ode/>
            </contact>
            <bounce/>
            <friction>
              <torsional>
                <ode/>
              </torsional>
              <ode/>
            </friction>
          </surface>
        </collision>
        <visual name='r_wrist_slider_eq_link_visual'>
          <pose frame=''>0.04 0.211 -0.749 0 -0 0</pose>
          <geometry>
            <mesh>
              <scale>0.001 0.001 0.001</scale>
              <uri>model://cer/meshes/dae/sim_cer_r_wrist_slider.dae</uri>
            </mesh>
          </geometry>
        </visual>
        <self_collide>0</self_collide>
        <enable_wind>0</enable_wind>
        <kinematic>0</kinematic>
      </link>
      <joint name='r_wrist_heave_eq_joint' type='prismatic'>
        <child>r_wrist_slider_eq_link</child>
        <parent>r_forearm_link</parent>
        <axis>
          <xyz>-0 0 -1</xyz>
          <limit>
            <lower>0</lower>
            <upper>0.13</upper>
            <effort>200</effort>
            <velocity>0.25</velocity>
          </limit>
          <dynamics>
            <damping>100</damping>
            <friction>0</friction>
            <spring_reference>0</spring_reference>
            <spring_stiffness>0</spring_stiffness>
          </dynamics>
          <use_parent_model_frame>1</use_parent_model_frame>
        </axis>
        <physics>
          <ode>
            <implicit_spring_damper>1</implicit_spring_damper>
            <cfm_damping>1</cfm_damping>
            <limit>
              <cfm>0</cfm>
              <erp>0.2</erp>
            </limit>
          </ode>
        </physics>
      </joint>
      <link name='r_wrist_cup_eq_link'>
        <pose frame=''>-0.072 -0.211 0.298 0 -0 1.5708</pose>
        <inertial>
          <pose frame=''>-1.1e-05 -0.031941 -0.018146 0 -0 0</pose>
          <mass>0.2</mass>
          <inertia>
            <ixx>0.000102239</ixx>
            <ixy>0</ixy>
            <ixz>3.78925e-08</ixz>
            <iyy>0.000102239</iyy>
            <iyz>0</iyz>
            <izz>0.000163555</izz>
          </inertia>
        </inertial>
        <collision name='r_wrist_cup_eq_link_collision'>
          <pose frame=''>0.04 0.179 -0.458 0 -0 0</pose>
          <geometry>
            <mesh>
              <scale>0.001 0.001 0.001</scale>
              <uri>model://cer/meshes/dae/sim_cer_r_wrist_cup_eq.dae</uri>
            </mesh>
          </geometry>
          <max_contacts>10</max_contacts>
          <surface>
            <contact>
              <ode/>
            </contact>
            <bounce/>
            <friction>
              <torsional>
                <ode/>
              </torsional>
              <ode/>
            </friction>
          </surface>
        </collision>
        <visual name='r_wrist_cup_eq_link_visual'>
          <pose frame=''>0.04 0.179 -0.458 0 -0 0</pose>
          <geometry>
            <mesh>
              <scale>0.001 0.001 0.001</scale>
              <uri>model://cer/meshes/dae/sim_cer_r_wrist_cup_eq.dae</uri>
            </mesh>
          </geometry>
        </visual>
        <self_collide>0</self_collide>
        <enable_wind>0</enable_wind>
        <kinematic>0</kinematic>
      </link>
      <joint name='r_wrist_roll_eq_joint' type='revolute'>
        <child>r_wrist_cup_eq_link</child>
        <parent>r_wrist_slider_eq_link</parent>
        <axis>
          <xyz>-1 0 0</xyz>
          <limit>
            <lower>-0.523599</lower>
            <upper>0.523599</upper>
            <effort>10</effort>
            <velocity>3.14</velocity>
          </limit>
          <dynamics>
            <damping>10</damping>
            <friction>0</friction>
            <spring_reference>0</spring_reference>
            <spring_stiffness>0</spring_stiffness>
          </dynamics>
          <use_parent_model_frame>1</use_parent_model_frame>
        </axis>
        <physics>
          <ode>
            <implicit_spring_damper>1</implicit_spring_damper>
            <cfm_damping>1</cfm_damping>
            <limit>
              <cfm>0</cfm>
              <erp>0.2</erp>
            </limit>
          </ode>
        </physics>
      </joint>
      <link name='r_hand_root_link'>
        <pose frame=''>-0.04 -0.211 0.298 0 -0 0</pose>
        <inertial>
          <pose frame=''>0.000191 0.013614 -0.06234 0 -0 0</pose>
          <mass>0.3</mass>
          <inertia>
            <ixx>0.000294522</ixx>
            <ixy>-1.41036e-06</ixy>
            <ixz>6.91732e-08</ixz>
            <iyy>0.000297774</iyy>
            <iyz>2.11461e-05</iyz>
            <izz>0.000189897</izz>
          </inertia>
        </inertial>
        <collision name='r_hand_root_link_collision'>
          <pose frame=''>0.04 0.211 -0.458 0 -0 0</pose>
          <geometry>
            <mesh>
              <scale>0.001 0.001 0.001</scale>
              <uri>model://cer/meshes/dae/sim_cer_r_hand_root.dae</uri>
            </mesh>
          </geometry>
          <max_contacts>10</max_contacts>
          <surface>
            <contact>
              <ode/>
            </contact>
            <bounce/>
            <friction>
              <torsional>
                <ode/>
              </torsional>
              <ode/>
            </friction>
          </surface>
        </collision>
        <visual name='r_hand_root_link_visual'>
          <pose frame=''>0.04 0.211 -0.458 0 -0 0</pose>
          <geometry>
            <mesh>
              <scale>0.001 0.001 0.001</scale>
              <uri>model://cer/meshes/dae/sim_cer_r_hand_root.dae</uri>
            </mesh>
          </geometry>
        </visual>
        <self_collide>0</self_collide>
        <enable_wind>0</enable_wind>
        <kinematic>0</kinematic>
      </link>
      <joint name='r_wrist_pitch_eq_joint' type='revolute'>
        <child>r_hand_root_link</child>
        <parent>r_wrist_cup_eq_link</parent>
        <axis>
          <xyz>-0 -1 -0</xyz>
          <limit>
            <lower>-0.523599</lower>
            <upper>0.523599</upper>
            <effort>10</effort>
            <velocity>3.14</velocity>
          </limit>
          <dynamics>
            <damping>10</damping>
            <friction>0</friction>
            <spring_reference>0</spring_reference>
            <spring_stiffness>0</spring_stiffness>
          </dynamics>
          <use_parent_model_frame>1</use_parent_model_frame>
        </axis>
        <physics>
          <ode>
            <implicit_spring_damper>1</implicit_spring_damper>
            <cfm_damping>1</cfm_damping>
            <limit>
              <cfm>0</cfm>
              <erp>0.2</erp>
            </limit>
          </ode>
        </physics>
      </joint>
      <link name='r_hand_paddle_proximal_link'>
        <pose frame=''>-0.04 -0.198143 0.185494 0 -0 0</pose>
        <inertial>
          <pose frame=''>-9.7e-05 -0.010867 -0.022258 0 -0 0</pose>
          <mass>0.05</mass>
          <inertia>
            <ixx>0.0001</ixx>
            <ixy>6.93652e-09</ixy>
            <ixz>1.75564e-08</ixz>
            <iyy>0.0001</iyy>
            <iyz>-1.81901e-06</iyz>
            <izz>0.0001</izz>
          </inertia>
        </inertial>
        <collision name='r_hand_paddle_proximal_link_collision'>
          <pose frame=''>0.04 0.198143 -0.345494 0 -0 0</pose>
          <geometry>
            <mesh>
              <scale>0.001 0.001 0.001</scale>
              <uri>model://cer/meshes/dae/sim_cer_r_hand_paddle_proximal.dae</uri>
            </mesh>
          </geometry>
          <max_contacts>10</max_contacts>
          <surface>
            <contact>
              <ode/>
            </contact>
            <bounce/>
            <friction>
              <torsional>
                <ode/>
              </torsional>
              <ode/>
            </friction>
          </surface>
        </collision>
        <visual name='r_hand_paddle_proximal_link_visual'>
          <pose frame=''>0.04 0.198143 -0.345494 0 -0 0</pose>
          <geometry>
            <mesh>
              <scale>0.001 0.001 0.001</scale>
              <uri>model://cer/meshes/dae/sim_cer_r_hand_paddle_proximal.dae</uri>
            </mesh>
          </geometry>
        </visual>
        <self_collide>0</self_collide>
        <enable_wind>0</enable_wind>
        <kinematic>0</kinematic>
      </link>
      <joint name='r_hand_paddle_proximal_joint' type='revolute'>
        <child>r_hand_paddle_proximal_link</child>
        <parent>r_hand_root_link</parent>
        <axis>
          <xyz>1 0 -0</xyz>
          <limit>
            <lower>0</lower>
            <upper>1.22173</upper>
            <effort>5</effort>
            <velocity>3.14</velocity>
          </limit>
          <dynamics>
            <damping>10</damping>
            <friction>0</friction>
            <spring_reference>0</spring_reference>
            <spring_stiffness>0</spring_stiffness>
          </dynamics>
          <use_parent_model_frame>1</use_parent_model_frame>
        </axis>
        <physics>
          <ode>
            <implicit_spring_damper>1</implicit_spring_damper>
            <cfm_damping>1</cfm_damping>
            <limit>
              <cfm>0</cfm>
              <erp>0.2</erp>
            </limit>
          </ode>
        </physics>
      </joint>
      <link name='r_hand_paddle_distal_link'>
        <pose frame=''>-0.04 -0.214471 0.146748 0 -0 0</pose>
        <inertial>
          <pose frame=''>0.001321 -0.005592 -0.020601 0 -0 0</pose>
          <mass>0.05</mass>
          <inertia>
            <ixx>0.0001</ixx>
            <ixy>1.94983e-07</ixy>
            <ixz>9.0126e-07</ixz>
            <iyy>0.0001</iyy>
            <iyz>-6.79853e-07</iyz>
            <izz>0.0001</izz>
          </inertia>
        </inertial>
        <collision name='r_hand_paddle_distal_link_collision'>
          <pose frame=''>0.04 0.214471 -0.306748 0 -0 0</pose>
          <geometry>
            <mesh>
              <scale>0.001 0.001 0.001</scale>
              <uri>model://cer/meshes/dae/sim_cer_r_hand_paddle_distal.dae</uri>
            </mesh>
          </geometry>
          <max_contacts>10</max_contacts>
          <surface>
            <contact>
              <ode/>
            </contact>
            <bounce/>
            <friction>
              <torsional>
                <ode/>
              </torsional>
              <ode/>
            </friction>
          </surface>
        </collision>
        <visual name='r_hand_paddle_distal_link_visual'>
          <pose frame=''>0.04 0.214471 -0.306748 0 -0 0</pose>
          <geometry>
            <mesh>
              <scale>0.001 0.001 0.001</scale>
              <uri>model://cer/meshes/dae/sim_cer_r_hand_paddle_distal.dae</uri>
            </mesh>
          </geometry>
        </visual>
        <self_collide>0</self_collide>
        <enable_wind>0</enable_wind>
        <kinematic>0</kinematic>
      </link>
      <joint name='r_hand_paddle_distal_joint' type='revolute'>
        <child>r_hand_paddle_distal_link</child>
        <parent>r_hand_paddle_proximal_link</parent>
        <axis>
          <xyz>1 0 -0</xyz>
          <limit>
            <lower>0</lower>
            <upper>1.22173</upper>
            <effort>5</effort>
            <velocity>3.14</velocity>
          </limit>
          <dynamics>
            <damping>10</damping>
            <friction>0</friction>
            <spring_reference>0</spring_reference>
            <spring_stiffness>0</spring_stiffness>
          </dynamics>
          <use_parent_model_frame>1</use_parent_model_frame>
        </axis>
        <physics>
          <ode>
            <implicit_spring_damper>1</implicit_spring_damper>
            <cfm_damping>1</cfm_damping>
            <limit>
              <cfm>0</cfm>
              <erp>0.2</erp>
            </limit>
          </ode>
        </physics>
      </joint>
      <link name='r_hand_thumb_proximal_link'>
        <pose frame=''>-0.04 -0.171352 0.222282 0 -0 0</pose>
        <inertial>
          <pose frame=''>0.002515 0.017936 -0.003159 0 -0 0</pose>
          <mass>0.05</mass>
          <inertia>
            <ixx>0.0001</ixx>
            <ixy>1.49367e-09</ixy>
            <ixz>3.12525e-10</ixz>
            <iyy>0.0001</iyy>
            <iyz>2.63475e-06</iyz>
            <izz>0.0001</izz>
          </inertia>
        </inertial>
        <collision name='r_hand_thumb_proximal_link_collision'>
          <pose frame=''>0.04 0.171352 -0.382282 0 -0 0</pose>
          <geometry>
            <mesh>
              <scale>0.001 0.001 0.001</scale>
              <uri>model://cer/meshes/dae/sim_cer_r_hand_thumb_proximal.dae</uri>
            </mesh>
          </geometry>
          <max_contacts>10</max_contacts>
          <surface>
            <contact>
              <ode/>
            </contact>
            <bounce/>
            <friction>
              <torsional>
                <ode/>
              </torsional>
              <ode/>
            </friction>
          </surface>
        </collision>
        <visual name='r_hand_thumb_proximal_link_visual'>
          <pose frame=''>0.04 0.171352 -0.382282 0 -0 0</pose>
          <geometry>
            <mesh>
              <scale>0.001 0.001 0.001</scale>
              <uri>model://cer/meshes/dae/sim_cer_r_hand_thumb_proximal.dae</uri>
            </mesh>
          </geometry>
        </visual>
        <self_collide>0</self_collide>
        <enable_wind>0</enable_wind>
        <kinematic>0</kinematic>
      </link>
      <joint name='r_hand_thumb_proximal_joint' type='revolute'>
        <child>r_hand_thumb_proximal_link</child>
        <parent>r_hand_root_link</parent>
        <axis>
          <xyz>-1 -0 0</xyz>
          <limit>
            <lower>0</lower>
            <upper>1.0472</upper>
            <effort>5</effort>
            <velocity>3.14</velocity>
          </limit>
          <dynamics>
            <damping>10</damping>
            <friction>0</friction>
            <spring_reference>0</spring_reference>
            <spring_stiffness>0</spring_stiffness>
          </dynamics>
          <use_parent_model_frame>1</use_parent_model_frame>
        </axis>
        <physics>
          <ode>
            <implicit_spring_damper>1</implicit_spring_damper>
            <cfm_damping>1</cfm_damping>
            <limit>
              <cfm>0</cfm>
              <erp>0.2</erp>
            </limit>
          </ode>
        </physics>
      </joint>
      <link name='r_hand_thumb_distal_link'>
        <pose frame=''>-0.04 -0.130827 0.211296 0 -0 0</pose>
        <inertial>
          <pose frame=''>0.002448 0.014529 -0.005865 0 -0 0</pose>
          <mass>0.05</mass>
          <inertia>
            <ixx>3.85163e-06</ixx>
            <ixy>-1.50194e-10</ixy>
            <ixz>4.04682e-10</ixz>
            <iyy>7.40388e-06</iyy>
            <iyz>9.14021e-07</iyz>
            <izz>8.52416e-06</izz>
          </inertia>
        </inertial>
        <collision name='r_hand_thumb_distal_link_collision'>
          <pose frame=''>0.04 0.130827 -0.371296 0 -0 0</pose>
          <geometry>
            <mesh>
              <scale>0.001 0.001 0.001</scale>
              <uri>model://cer/meshes/dae/sim_cer_r_hand_thumb_distal.dae</uri>
            </mesh>
          </geometry>
          <max_contacts>10</max_contacts>
          <surface>
            <contact>
              <ode/>
            </contact>
            <bounce/>
            <friction>
              <torsional>
                <ode/>
              </torsional>
              <ode/>
            </friction>
          </surface>
        </collision>
        <visual name='r_hand_thumb_distal_link_visual'>
          <pose frame=''>0.04 0.130827 -0.371296 0 -0 0</pose>
          <geometry>
            <mesh>
              <scale>0.001 0.001 0.001</scale>
              <uri>model://cer/meshes/dae/sim_cer_r_hand_thumb_distal.dae</uri>
            </mesh>
          </geometry>
        </visual>
        <self_collide>0</self_collide>
        <enable_wind>0</enable_wind>
        <kinematic>0</kinematic>
      </link>
      <joint name='r_hand_thumb_distal_joint' type='revolute'>
        <child>r_hand_thumb_distal_link</child>
        <parent>r_hand_thumb_proximal_link</parent>
        <axis>
          <xyz>-1 -0 0</xyz>
          <limit>
            <lower>0</lower>
            <upper>1.22173</upper>
            <effort>5</effort>
            <velocity>3.14</velocity>
          </limit>
          <dynamics>
            <damping>10</damping>
            <friction>0</friction>
            <spring_reference>0</spring_reference>
            <spring_stiffness>0</spring_stiffness>
          </dynamics>
          <use_parent_model_frame>1</use_parent_model_frame>
        </axis>
        <physics>
          <ode>
            <implicit_spring_damper>1</implicit_spring_damper>
            <cfm_damping>1</cfm_damping>
            <limit>
              <cfm>0</cfm>
              <erp>0.2</erp>
            </limit>
          </ode>
        </physics>
      </joint>
      <joint name='fixed to ground' type='fixed'>
        <parent>world</parent>
        <child>mobile_base_body_link</child>
        <axis>
          <limit>
            <lower>0</lower>
            <upper>0</upper>
          </limit>
          <xyz>0 1 0</xyz>
          <use_parent_model_frame>0</use_parent_model_frame>
        </axis>
      </joint>
      <plugin name='controlboard_torso' filename='libgazebo_yarp_controlboard.so'>
        <yarpConfigurationFile>model://cer/conf/gazebo_cer_torso.ini</yarpConfigurationFile>
      </plugin>
      <plugin name='controlboard_torso_tripod' filename='libgazeboTripod.so'>
        <yarpConfigurationFile>model://cer/conf/gazebo_cer_torso_tripod.ini</yarpConfigurationFile>
      </plugin>
      <plugin name='controlboard_left_upper_arm' filename='libgazebo_yarp_controlboard.so'>
        <yarpConfigurationFile>model://cer/conf/gazebo_cer_left_upper_arm.ini</yarpConfigurationFile>
      </plugin>
      <plugin name='controlboard_left_wrist' filename='libgazebo_yarp_controlboard.so'>
        <yarpConfigurationFile>model://cer/conf/gazebo_cer_left_wrist.ini</yarpConfigurationFile>
      </plugin>
      <plugin name='controlboard_left_wrist_tripod' filename='libgazeboTripod.so'>
        <yarpConfigurationFile>model://cer/conf/gazebo_cer_left_wrist_tripod.ini</yarpConfigurationFile>
      </plugin>
      <plugin name='controlboard_right_upper_arm' filename='libgazebo_yarp_controlboard.so'>
        <yarpConfigurationFile>model://cer/conf/gazebo_cer_right_upper_arm.ini</yarpConfigurationFile>
      </plugin>
      <plugin name='controlboard_right_wrist' filename='libgazebo_yarp_controlboard.so'>
        <yarpConfigurationFile>model://cer/conf/gazebo_cer_right_wrist.ini</yarpConfigurationFile>
      </plugin>
      <plugin name='controlboard_right_wrist_tripod' filename='libgazeboTripod.so'>
        <yarpConfigurationFile>model://cer/conf/gazebo_cer_right_wrist_tripod.ini</yarpConfigurationFile>
      </plugin>
      <plugin name='controlboard_right_arm' filename='libgazebo_yarp_controlboard.so'>
        <yarpConfigurationFile>model://cer/conf/gazebo_cer_right_arm.ini</yarpConfigurationFile>
      </plugin>
      <plugin name='controlboard_left_arm' filename='libgazebo_yarp_controlboard.so'>
        <yarpConfigurationFile>model://cer/conf/gazebo_cer_left_arm.ini</yarpConfigurationFile>
      </plugin>
      <plugin name='controlboard_head' filename='libgazebo_yarp_controlboard.so'>
        <yarpConfigurationFile>model://cer/conf/gazebo_cer_head.ini</yarpConfigurationFile>
      </plugin>
      <plugin name='controlboard_left_hand' filename='libgazebo_yarp_controlboard.so'>
        <yarpConfigurationFile>model://cer/conf/gazebo_cer_left_hand.ini</yarpConfigurationFile>
      </plugin>
      <plugin name='controlboard_right_hand' filename='libgazebo_yarp_controlboard.so'>
        <yarpConfigurationFile>model://cer/conf/gazebo_cer_right_hand.ini</yarpConfigurationFile>
      </plugin>
      <plugin name='mais_left_hand' filename='libgazebo_yarp_maissensor.so'>
        <yarpConfigurationFile>model://cer/conf/gazebo_cer_left_hand_mais.ini</yarpConfigurationFile>
      </plugin>
      <plugin name='mais_right_hand' filename='libgazebo_yarp_maissensor.so'>
        <yarpConfigurationFile>model://cer/conf/gazebo_cer_right_hand_mais.ini</yarpConfigurationFile>
      </plugin>
      <plugin name='controlboard_mobile_base' filename='libgazebo_yarp_controlboard.so'>
        <yarpConfigurationFile>model://cer/conf/gazebo_cer_mobile_base.ini</yarpConfigurationFile>
      </plugin>
      <plugin name='controlboard_all' filename='libgazebo_yarp_controlboard.so'>
        <yarpConfigurationFile>model://cer/conf/gazebo_cer_all.ini</yarpConfigurationFile>
      </plugin>
      <plugin name='world_interface' filename='libgazebo_yarp_worldinterface.so'>
        <yarpConfigurationFile>model://cer/conf/worldInterface.ini</yarpConfigurationFile>
      </plugin>
      <static>0</static>
      <pose frame=''>2.01144 -1.05759 0.16 0 -0 0</pose>
    </model>
    <state world_name='default'>
      <sim_time>209 797000000</sim_time>
      <real_time>93 226174009</real_time>
      <wall_time>1558009501 981894263</wall_time>
      <iterations>91948</iterations>
      <model name='SIM_CER_ROBOT'>
        <pose frame=''>2.01144 -1.05759 0.16 0 -0 0</pose>
        <scale>1 1 1</scale>
        <link name='chest_link'>
          <pose frame=''>2.05544 -1.05759 0.629997 1e-06 -0.002467 4.9e-05</pose>
          <velocity>-0 -0 -0 -7.1e-05 -2.4e-05 -0.00028</velocity>
          <acceleration>-0.000343 -7.6e-05 -5.2e-05 0.00178 -0.001506 -0.009541</acceleration>
          <wrench>-0.004458 -0.000991 -0.000677 0 -0 0</wrench>
        </link>
        <link name='head_link'>
          <pose frame=''>1.97208 -1.0576 1.18815 2e-06 -0.000357 4.9e-05</pose>
          <velocity>-1e-05 6.3e-05 -2e-06 -7.2e-05 -3e-06 -0.000282</velocity>
          <acceleration>-0.001304 -0.000963 3.7e-05 -0.000688 -0.004363 -0.024271</acceleration>
          <wrench>-0.002608 -0.001926 7.4e-05 0 -0 0</wrench>
        </link>
        <link name='l_clavicle_link'>
          <pose frame=''>1.97052 -0.880594 0.999787 1.7e-05 -0.002473 4.7e-05</pose>
          <velocity>4.1e-05 5e-05 -1.5e-05 -7.8e-05 0.000154 -0.000244</velocity>
          <acceleration>0.001111 0.000157 0.000211 0.002462 0.018839 -0.005493</acceleration>
          <wrench>0.000222 3.1e-05 4.2e-05 0 -0 0</wrench>
        </link>
        <link name='l_elbow_sphere_link'>
          <pose frame=''>1.97114 -0.846708 0.748771 -0.000397 -0.002473 5.3e-05</pose>
          <velocity>1.1e-05 1.1e-05 -2e-05 -0.000214 0.000872 -0.000243</velocity>
          <acceleration>-0.003356 0.001809 0.000437 0.00243 0.064401 -0.01235</acceleration>
          <wrench>-0.000671 0.000362 8.7e-05 0 -0 0</wrench>
        </link>
        <link name='l_forearm_link'>
          <pose frame=''>1.97131 -0.84674 0.677771 -0.000406 -0.002474 4.9e-05</pose>
          <velocity>-4.5e-05 0 -2e-05 -0.000201 0.000855 -0.00023</velocity>
          <acceleration>-0.012234 0.00261 0.000445 0.003699 0.063521 -0.022843</acceleration>
          <wrench>-0.007341 0.001566 0.000267 0 -0 0</wrench>
        </link>
        <link name='l_hand_paddle_distal_link'>
          <pose frame=''>1.97225 -0.843383 0.300655 -0.000281 -0.002466 4.9e-05</pose>
          <velocity>-0.000366 -8.1e-05 -4.1e-05 -0.000235 0.000845 -0.000234</velocity>
          <acceleration>-0.034597 0.002817 0.000766 -0.002402 0.073585 -0.018818</acceleration>
          <wrench>-0.00173 0.000141 3.8e-05 0 -0 0</wrench>
        </link>
        <link name='l_hand_paddle_proximal_link'>
          <pose frame=''>1.97215 -0.859702 0.339405 -0.000227 -0.002466 4.9e-05</pose>
          <velocity>-0.000338 -7.2e-05 -3.7e-05 -0.000235 0.000846 -0.000234</velocity>
          <acceleration>-0.032064 0.002891 0.000892 -0.001422 0.067747 -0.01886</acceleration>
          <wrench>-0.001603 0.000145 4.5e-05 0 -0 0</wrench>
        </link>
        <link name='l_hand_root_link'>
          <pose frame=''>1.97187 -0.846831 0.451909 -0.000125 -0.002466 4.9e-05</pose>
          <velocity>-0.000239 -4.6e-05 -4e-05 -0.000232 0.000845 -0.000234</velocity>
          <acceleration>-0.026928 0.002959 0.000901 -0.006526 0.093242 0.077919</acceleration>
          <wrench>-0.008078 0.000888 0.00027 0 -0 0</wrench>
        </link>
        <link name='l_hand_thumb_distal_link'>
          <pose frame=''>1.97235 -0.927013 0.365207 0.000219 -0.002465 4.9e-05</pose>
          <velocity>-0.000331 -6.6e-05 -2.2e-05 -0.000228 0.000842 -0.000235</velocity>
          <acceleration>-0.030682 0.002899 0.000774 -0.000555 0.072232 -0.018863</acceleration>
          <wrench>-0.001534 0.000145 3.9e-05 0 -0 0</wrench>
        </link>
        <link name='l_hand_thumb_proximal_link'>
          <pose frame=''>1.97206 -0.886489 0.376196 9.8e-05 -0.002465 5e-05</pose>
          <velocity>-0.000313 -6.4e-05 -3.1e-05 -0.000229 0.000842 -0.000235</velocity>
          <acceleration>-0.028976 0.002904 0.000752 -0.000554 0.054819 -0.019757</acceleration>
          <wrench>-0.001449 0.000145 3.8e-05 0 -0 0</wrench>
        </link>
        <link name='l_shoulder_link'>
          <pose frame=''>1.97052 -0.880594 0.999786 -0.000451 -0.002472 4.8e-05</pose>
          <velocity>4.1e-05 5e-05 -1.4e-05 -0.000159 0.000156 -0.000242</velocity>
          <acceleration>0.000128 0.000577 0.000498 0.00793 0.673553 1.02558</acceleration>
          <wrench>6.4e-05 0.000289 0.000249 0 -0 0</wrench>
        </link>
        <link name='l_upperarm_FT_sensor_link'>
          <pose frame=''>1.97079 -0.846644 0.889771 -0.000448 -0.002472 5.2e-05</pose>
          <velocity>3.2e-05 3.3e-05 -2e-05 -0.000162 0.000159 -0.000237</velocity>
          <acceleration>-0.001548 0.001168 0.000452 0.002627 0.01952 -0.011504</acceleration>
          <wrench>-0.001239 0.000934 0.000362 0 -0 0</wrench>
        </link>
        <link name='l_wrist_cup_eq_link'>
          <pose frame=''>1.93987 -0.846833 0.45183 -0.000125 -0.002479 4.9e-05</pose>
          <velocity>-0.000239 -3.8e-05 -1.2e-05 -0.000236 0.000879 -0.000233</velocity>
          <acceleration>-0.023185 0.003058 0.000906 0.001507 0.064643 1.00854</acceleration>
          <wrench>-0.004637 0.000612 0.000181 0 -0 0</wrench>
        </link>
        <link name='l_wrist_slider_eq_link'>
          <pose frame=''>1.97115 -0.846714 0.742908 -0.000405 -0.002474 4.9e-05</pose>
          <velocity>1.2e-05 1.4e-05 -3.8e-05 -0.000204 0.00086 -0.000232</velocity>
          <acceleration>-0.01785 0.002918 0.000972 0.001391 0.06409 0.938704</acceleration>
          <wrench>-0.005355 0.000875 0.000292 0 -0 0</wrench>
        </link>
        <link name='mobile_base_body_link'>
          <pose frame=''>2.01144 -1.05759 0.16 0 -0 0</pose>
          <velocity>-0 -0 0 0 -0 0</velocity>
          <acceleration>0 -0 0 1e-06 2e-06 -1e-06</acceleration>
          <wrench>3e-06 -1e-06 0 0 -0 0</wrench>
        </link>
        <link name='mobile_base_l_tyre_link'>
          <pose frame=''>2.01144 -0.91859 0.16 0 -3.8e-05 0</pose>
          <velocity>-0 -0 -0 0 -0 0</velocity>
          <acceleration>0 -0 0 1e-06 -2.1e-05 -1e-06</acceleration>
          <wrench>0 -0 1e-06 0 -0 0</wrench>
        </link>
        <link name='mobile_base_r_tyre_link'>
          <pose frame=''>2.01144 -1.19659 0.16 0 -3.9e-05 0</pose>
          <velocity>0 -0 0 0 -0 0</velocity>
          <acceleration>-0 -0 -0 1e-06 -2.1e-05 -1e-06</acceleration>
          <wrench>-0 -0 -0 0 -0 0</wrench>
        </link>
        <link name='neck_link'>
          <pose frame=''>1.96045 -1.0576 1.02976 1e-06 -0.000356 4.8e-05</pose>
          <velocity>-1e-05 5.5e-05 -2e-06 -7.1e-05 -3e-06 -0.000279</velocity>
          <acceleration>-0.000952 3.6e-05 -0.000146 0.004285 -0.00436 0.002927</acceleration>
          <wrench>-0.001333 5e-05 -0.000205 0 -0 0</wrench>
        </link>
        <link name='r_clavicle_link'>
          <pose frame=''>1.97054 -1.23459 0.999789 -3e-06 -0.002452 4.4e-05</pose>
          <velocity>-5.8e-05 5e-05 1.1e-05 -6.6e-05 -0.000342 -0.000197</velocity>
          <acceleration>-0.00228 0.000137 -0.00045 0.001907 -0.022272 -0.005562</acceleration>
          <wrench>-0.000456 2.7e-05 -9e-05 0 -0 0</wrench>
        </link>
        <link name='r_elbow_sphere_link'>
          <pose frame=''>1.97115 -1.26847 0.748769 0.000495 -0.002453 3.2e-05</pose>
          <velocity>2.7e-05 1.1e-05 1.6e-05 -0.000145 0.000115 -0.000216</velocity>
          <acceleration>0.000993 0.001908 -0.000706 0.007895 0.001918 0.001953</acceleration>
          <wrench>0.000199 0.000382 -0.000141 0 -0 0</wrench>
        </link>
        <link name='r_forearm_link'>
          <pose frame=''>1.97133 -1.26844 0.677768 0.00045 -0.002443 5e-05</pose>
          <velocity>2.2e-05 -0 1.6e-05 -0.000203 -3e-06 -0.000256</velocity>
          <acceleration>-0.002086 0.002713 -0.000706 0.003103 0.026489 0.012075</acceleration>
          <wrench>-0.001251 0.001628 -0.000424 0 -0 0</wrench>
        </link>
        <link name='r_hand_paddle_distal_link'>
          <pose frame=''>1.97225 -1.27178 0.300648 0.00032 -0.002461 5e-05</pose>
          <velocity>3.4e-05 -8.3e-05 3.7e-05 -0.000233 -7.2e-05 -0.000259</velocity>
          <acceleration>-0.017172 0.002883 -0.001252 -0.001215 0.065147 0.010626</acceleration>
          <wrench>-0.000859 0.000144 -6.3e-05 0 -0 0</wrench>
        </link>
        <link name='r_hand_paddle_proximal_link'>
          <pose frame=''>1.97216 -1.25546 0.339399 0.00027 -0.002461 5e-05</pose>
          <velocity>3.5e-05 -7.4e-05 3.3e-05 -0.000233 -7.1e-05 -0.000259</velocity>
          <acceleration>-0.014846 0.002948 -0.001179 -0.002246 0.059152 0.010641</acceleration>
          <wrench>-0.000742 0.000147 -5.9e-05 0 -0 0</wrench>
        </link>
        <link name='r_hand_root_link'>
          <pose frame=''>1.97188 -1.26834 0.451902 0.000174 -0.00246 5e-05</pose>
          <velocity>2.4e-05 -4.8e-05 3.6e-05 -0.000228 -7.3e-05 -0.000257</velocity>
          <acceleration>-0.010252 0.003099 -0.001219 -0.003385 0.085486 -0.084056</acceleration>
          <wrench>-0.003076 0.00093 -0.000366 0 -0 0</wrench>
        </link>
        <link name='r_hand_thumb_distal_link'>
          <pose frame=''>1.97209 -1.18815 0.365203 -0.000159 -0.00246 5e-05</pose>
          <velocity>5.1e-05 -6.8e-05 1.8e-05 -0.000228 -7.3e-05 -0.000258</velocity>
          <acceleration>-0.0131 0.00307 -0.001539 -0.007706 -0.161892 -1.87041</acceleration>
          <wrench>-0.000655 0.000154 -7.7e-05 0 -0 0</wrench>
        </link>
        <link name='r_hand_thumb_proximal_link'>
          <pose frame=''>1.97206 -1.22868 0.376191 -4.6e-05 -0.00246 5e-05</pose>
          <velocity>3.9e-05 -6.5e-05 2.7e-05 -0.000228 -7.3e-05 -0.000258</velocity>
          <acceleration>-0.011783 0.003099 -0.001445 -0.001774 0.047175 0.00974</acceleration>
          <wrench>-0.000589 0.000155 -7.2e-05 0 -0 0</wrench>
        </link>
        <link name='r_shoulder_link'>
          <pose frame=''>1.97054 -1.2346 0.999787 0.000508 -0.002454 4.6e-05</pose>
          <velocity>-5.8e-05 5e-05 1.1e-05 -0.00015 -0.000361 -0.000204</velocity>
          <acceleration>-0.001578 0.000584 -0.000767 0.007572 0.688636 -1.07877</acceleration>
          <wrench>-0.000789 0.000292 -0.000383 0 -0 0</wrench>
        </link>
        <link name='r_upperarm_FT_sensor_link'>
          <pose frame=''>1.97081 -1.26854 0.889769 0.00049 -0.002453 3.3e-05</pose>
          <velocity>-2.5e-05 3.3e-05 1.6e-05 -0.000156 -0.00037 -0.000216</velocity>
          <acceleration>-0.000311 0.001214 -0.000716 0.00756 -0.01342 0.002004</acceleration>
          <wrench>-0.000249 0.000971 -0.000573 0 -0 0</wrench>
        </link>
        <link name='r_wrist_cup_eq_link'>
          <pose frame=''>1.93988 -1.26834 0.451824 -0.002443 -0.000176 1.57085</pose>
          <velocity>2.4e-05 -3.9e-05 3.6e-05 -0.00022 -6e-06 -0.000255</velocity>
          <acceleration>-0.006584 0.003259 -0.001169 -0.002063 0.027885 -1.23624</acceleration>
          <wrench>-0.001317 0.000652 -0.000234 0 -0 0</wrench>
        </link>
        <link name='r_wrist_slider_eq_link'>
          <pose frame=''>1.97117 -1.26847 0.742901 0.000449 -0.002442 5e-05</pose>
          <velocity>2.2e-05 1.3e-05 3.6e-05 -0.000205 -5e-06 -0.000256</velocity>
          <acceleration>-0.004464 0.00303 -0.001368 0.005217 0.027065 -0.91799</acceleration>
          <wrench>-0.001339 0.000909 -0.00041 0 -0 0</wrench>
        </link>
        <link name='torso_pin_eq_link'>
          <pose frame=''>2.05544 -1.05759 0.63 -3.14159 3.3e-05 0</pose>
          <velocity>-0 -0 0 -7.7e-05 1e-06 -0</velocity>
          <acceleration>-3e-06 3e-06 -0 0.002381 -0.000119 0.000115</acceleration>
          <wrench>-5e-06 5e-06 -0 0 -0 0</wrench>
        </link>
        <link name='torso_platform_link'>
          <pose frame=''>2.05544 -1.05759 0.629999 1e-06 -0.002364 -0</pose>
          <velocity>-0 -0 0 -7.3e-05 -2.1e-05 0</velocity>
          <acceleration>-7e-06 5e-06 -1e-06 0.001231 -0.001801 -0.00356</acceleration>
          <wrench>-1.1e-05 7e-06 -1e-06 0 -0 0</wrench>
        </link>
        <link name='torso_slider_eq_link'>
          <pose frame=''>2.05544 -1.05759 0.231 0 1e-06 0</pose>
          <velocity>-0 0 0 0 -0 0</velocity>
          <acceleration>-0 1e-06 0 -6e-06 -1.1e-05 2e-06</acceleration>
          <wrench>-1e-06 1e-05 1e-06 0 -0 0</wrench>
        </link>
      </model>
      <model name='ground_plane'>
        <pose frame=''>0 0 0 0 -0 0</pose>
        <scale>1 1 1</scale>
        <link name='link'>
          <pose frame=''>0 0 0 0 -0 0</pose>
          <velocity>0 0 0 0 -0 0</velocity>
          <acceleration>0 0 0 0 -0 0</acceleration>
          <wrench>0 0 0 0 -0 0</wrench>
        </link>
      </model>
      <light name='sun'>
        <pose frame=''>0 0 10 0 -0 0</pose>
      </light>
    </state>
    <gui fullscreen='0'>
      <camera name='user_camera'>
        <pose frame=''>5.19182 -1.01311 1.37546 0 0.287643 -3.13899</pose>
        <view_controller>orbit</view_controller>
        <projection_type>perspective</projection_type>
      </camera>
    </gui>
  </world>
</sdf>
